Workbook

Sheet Cálculo
T1: Variação
C2: FY | W2: Delta
B3: ="EBITDA "&D15 -> EBITDA FY26'B | C3: =[1]DRE!$O$30/1000 -> 632.04404 | E3: Cálculo | F3: Manual | H3: =H17+H19 -> 1046295.7 | M3: Atualizar | T3: =B3 -> EBITDA FY26'B | U3: =C3 -> 632.04404 | V3: 701.06246 | W3: =U3-V3 -> -69.018412
B4: Forex | C4: =SUM(E4:F4) -> 70.572859 | D4: 26.209989 | E4: =J153/1000 -> 70.572859 | F4: =SUMIF($J$155:$J$181,B4,$I$155:$I$181)/1000 -> 0 | H4: =F17+F19 -> 1840632.9 | T4: =B4 -> Forex | U4: =C4 -> 70.572859 | V4: -41.322712 | W4: =U4-V4 -> 111.89557
B5: Price | C5: =SUM(E5:F5) -> 286.54894 | D5: 17.600765 | E5: =M48/1000 -> 286.54894 | F5: =SUMIF($J$155:$J$181,B5,$I$155:$I$181)/1000 -> 0 | H5: =H3/H4*1000 -> 568.44344 | J5: Sales | K5: Var Vol (kt) | L5: Vol/Mix impact | M5: Price impact | P5: Price impact | Q5: Forex | T5: =B5 -> Price | U5: =C5 -> 286.54894 | V5: -79.358523 | W5: =U5-V5 -> 365.90747
B6: Volume | C6: =SUM(E6:F6) -> -23.126221 | D6: 4.2158522 | E6: =L114/1000 -> -23.126221 | F6: =SUMIF($J$155:$J$181,B6,$I$155:$I$181)/1000 -> 0 | H6: =H5-G18 -> 51.826059 | J6: External | K6: =SUM(J83,J84,J88,J94,J95,J99,J100,J104) -> 364878.98 | L6: =SUM(K83,K84,K88,K94,K95,K99,K100,K104) -> 4125.244 | M6: =SUM(M17,M18,M22,M28,M29,M33,M34,M38,M44) -> 175788.85 | P6: =SUM(P17,P18,P22,P28,P29,P33,P34,P38,P44) -> 177667.05 | Q6: =SUM(Q17,Q18,Q22,Q29,Q34,Q38,Q44) -> 0 | T6: =B6 -> Volume | U6: =C6 -> -23.126221 | V6: 3.2696067 | W6: =U6-V6 -> -26.395828 | X6: -85996.796 | Z6: =M6-X6 -> 261785.65
B7: Mix | C7: =SUM(E7:F7) -> 16.44584 | D7: 1.1809201 | E7: =I114/1000+I166/1000 -> 16.44584 | F7: =SUMIF($J$155:$J$181,B7,$I$155:$I$181)/1000 -> 0 | H7: =H6*F18 -> 51687532 | J7: Domestic | K7: =SUM(J86:J87,J89:J93,J96:J98,J101:J103,J105:J113) -> 58125.113 | L7: =SUM(K86:K87,K89:K93,K96:K98,K101:K103,K105:K109,K111,K110,K112,K113) -> 9448.1482 | M7: =SUM(M20:M21,M23:M27,M30:M32,M35:M37,M39:M47) -> 52139.579 | P7: =SUM(P20:P21,P23:P27,P30:P32,P35:P37,P39:P43,P45,P46,P47) -> 193662.29 | Q7: =SUM(Q20:Q21,Q23:Q27,Q30:Q32,Q35:Q37,Q39:Q47,Q28,Q33) -> 143400.91 | T7: =B7 -> Mix | U7: =C7 -> 16.44584 | V7: 11.585407 | W7: =U7-V7 -> 4.8604336 | X7: 121689.4 | Z7: =M7-X7 -> -69549.819
B8: Fixed cost | C8: =SUM(E8:F8) -> -34.290559 | D8: 0 | E8: =J126/1000 -> -34.290559 | F8: =SUMIF($J$155:$J$181,B8,$I$155:$I$181)/1000 -> 0 | J8: Total | K8: =SUM(K6:K7) -> 423004.09 | L8: =SUM(L6:L7) -> 13573.392 | M8: =SUM(M6:M7) -> 227928.43 | P8: =SUM(P6:P7) -> 371329.34 | Q8: =SUM(Q6:Q7) -> 143400.91 | T8: =B8 -> Fixed cost | U8: =C8 -> -34.290559 | V8: -4.2325994 | W8: =U8-V8 -> -30.057959 | X8: 35692.602 | Z8: =M8-X8 -> 192235.83
B9: Input price | C9: =SUM(E9:F9) -> -177.47195 | D9: -60.287404 | E9: =J145/1000 -> -177.47195 | F9: =SUMIF($J$155:$J$181,B9,$I$155:$I$181)/1000 -> 0 | P9: =P8-P48 -> -58620.514 | T9: =B9 -> Input price | U9: =C9 -> -177.47195 | V9: 76.679374 | W9: =U9-V9 -> -254.15132 | Z9: =X9-M9 -> 0
B10: Usage | C10: =SUM(E10:F10) -> -12.829343 | D10: -3.3109603 | E10: =J148/1000 -> -12.829343 | F10: =SUMIF($J$155:$J$181,B10,$I$155:$I$181)/1000 -> 0 | J10: Industry | K10: =SUM(J86:J87,J90,J93,J97,J102,J105,J108,J91,J98,J103,J106,J110,J111,J112,J113) -> 45691.088 | L10: =SUM(K86:K87,K90,K93,K97,K102,K105,K108,K91,K98,K103,K106,K111,K110,K112) -> 4371.2704 | M10: =SUM(M20:M21,M24,M27,M31,M36,M39,M42,M25,M32,M37,M40)+M47+M46+M45 -> 40156.697 | P10: =SUM(P20:P21,P24,P27,P31,P36,P39,P42,P25,P32,P37,P40,P45) -> 144239.63 | Q10: =SUM(Q20:Q21,Q24,Q27,Q31,Q36,Q39,Q42:Q47,Q25,Q32,Q37,Q40)-Q43 -> 104082.93 | T10: =B10 -> Usage | U10: =C10 -> -12.829343 | V10: 2.1295159 | W10: =U10-V10 -> -14.958859 | X10: 129883.42 | Z10: =M10-X10 -> -89726.719
B11: Others | C11: =SUM(E11:F11) -> -5.7640204 | D11: -2.376185 | F11: =SUMIF($J$155:$J$181,B11,$I$155:$I$181)/1000 -> -5.7640204 | J11: Auto | K11: =SUM(J89,J92,J96,J101,J107,J109) -> 12434.025 | L11: =SUM(K89,K92,K96,K101,K107,K109) -> 5076.8778 | M11: =SUM(M23,M26,M30,M35,M41,M43) -> 11982.881 | N11: =M10-M20-M21 -> 40575.522 | P11: =SUM(P23,P26,P30,P35,P41,P43) -> 49422.664 | Q11: =SUM(Q23,Q26,Q30,Q35,Q41,Q43,Q28,Q33) -> 39317.984 | T11: =B11 -> Others | U11: =C11 -> -5.7640204 | V11: -5.0983695 | W11: =U11-V11 -> -0.66565089 | X11: -8194.0185 | Y11: 130619.12 | Z11: =M11-X11 -> 20176.9
B12: Stock variation | C12: =C13-SUM(C3:C11) -> -4.4371962 | D12: -25.205747 | F12: =SUMIF($J$155:$J$181,B12,$I$155:$I$181)/1000 -> -3.8604225 | J12: Check | K12: =K7-K10-K11 -> 0 | L12: =L7-L10-L11 -> 0 | M12: =M7-M10-M11 -> 0 | P12: =P7-P10-P11 -> 0 | Q12: =Q7-Q10-Q11 -> 0 | T12: =B12 -> Stock variation | U12: =C12 -> -4.4371962 | V12: 46.24153 | W12: =U12-V12 -> -50.678726 | Z12: =N11-Y11 -> -90043.601
B13: ="EBITDA "&G15 -> EBITDA FY26'F7 | C13: =[2]DRE!$O$30/1000 -> 747.6924 | F13: =F48-F14 -> 0 | J13: Industry & Down KUSD | K13: =SUM(H24:H25,H27,H31:H32,H36:H37,H39:H40,H42) -> 2460560.9 | N13: =K10-J86-J87 -> 45737.768 | P13: =P8/1000 -> 371.32934 | T13: =B13 -> EBITDA FY26'F7 | U13: =C13 -> 747.6924 | V13: 710.95569 | W13: =U13-V13 -> 36.736715 | Z13: =Z10-Z12 -> 316.88205
C14: ='[3]Shipments & Prices'!$O$8*1000-C48 -> -0.38 | E14: =E48-'[3]Shipments & Prices'!$O$234 -> 0.1558374 | F14: ='[4]Shipments & Prices'!$O$20*1000 -> 7106558.5 | H14: ='[4]Shipments & Prices'!$O$234-H48 -> 0 | J14: Auto KUSD | K14: =SUM(H23,H26,H30,H35,H41,H43,H20,H21) -> 930071.95
D15: FY26'B | G15: FY26'F7 | V15: =V10-U10 -> 14.958859
B16: Sales | C16: kt | D16: USD/t | E16: kUSD | F16: kt | G16: USD/t | H16: kUSD | I16: Sales Mix | J16: Mix Working | K16: Var Price USD | L16: Var Price BRL | M16: Price impact | O16: Var Price USD | P16: Price impact | Q16: Forex
B17: Slab Calvert | C17: ='[3]Shipments & Prices'!$O$23*1000 -> 961000 | D17: =IF(ISERROR((+E17/C17)*1000),0,(+E17/C17)*1000) -> 521.64672 | E17: ='[3]Shipments & Prices'!$O$237 -> 501302.5 | F17: ='[4]Shipments & Prices'!$O$23*1000 -> 966247.87 | G17: =IF(ISERROR((+H17/F17)*1000),0,(+H17/F17)*1000) -> 611.989 | H17: ='[4]Shipments & Prices'!$O$237 -> 591333.07 | I17: =(F17-J17)*D17/1000 -> 11455.529 | J17: =$F$48*C17/$C$48 -> 944287.55 | K17: =G17-D17 -> 90.342283 | M17: =K17*F17/1000 -> 87293.039 | N17: =H17-E17 -> 90030.573 | O17: =G17-D17 -> 90.342283 | P17: =O17*F17/1000 -> 87293.039 | Q17: =P17-M17 -> 0 | R17: =C17-F17 -> -5247.87
B18: Slabs Others Intragroup | C18: =[5]TUBARÃO_VEGA!$O$614*1000 -> 400000 | D18: =IF(ISERROR((+E18/C18)*1000),0,(+E18/C18)*1000) -> 444.574 | E18: =[5]TUBARÃO_VEGA!$O$626 -> 177829.6 | F18: ='[4]Shipments & Prices'!$O$614*1000 -> 997327.08 | G18: =IF(ISERROR((+H18/F18)*1000),0,(+H18/F18)*1000) -> 516.61738 | H18: ='[4]Shipments & Prices'!$O$626 -> 515236.51 | I18: =(F18-J18)*D18/1000 -> 268648.67 | J18: =$F$48*C18/$C$48 -> 393043.73 | K18: =G18-D18 -> 72.04338 | M18: =K18*F18/1000 -> 71850.814 | O18: =G18-D18 -> 72.04338 | P18: =O18*F18/1000 -> 71850.814 | Q18: =P18-M18 -> 0 | T18: 1789
B19: Slabs 3rd Party | C19: =[5]TUBARÃO_VEGA!$O$615*1000 -> 1423164.4 | D19: =IF(ISERROR((+E19/C19)*1000),0,(+E19/C19)*1000) -> 453.281 | E19: =[5]TUBARÃO_VEGA!$O$627 -> 645093.38 | F19: ='[4]Shipments & Prices'!$O$615*1000 -> 874385.04 | G19: =IF(ISERROR((+H19/F19)*1000),0,(+H19/F19)*1000) -> 520.32299 | H19: ='[4]Shipments & Prices'!$O$627 -> 454962.64 | I19: =(F19-J19)*D19/1000 -> -237532.63 | J19: =$F$48*C19/$C$48 -> 1398414.6 | K19: =G19-D19 -> 67.04199 | M19: =K19*F19/1000 -> 58620.514 | O19: =G19-D19 -> 67.04199 | P19: =O19*F19/1000 -> 58620.514 | Q19: =P19-M19 -> 0
B20: Slab DM | C20: ='[3]Shipments & Prices'!$O$25*1000 -> 31000 | D20: =IF(ISERROR((+E20/C20)*1000),0,(+E20/C20)*1000) -> 451.10154 | E20: ='[3]Shipments & Prices'!$O$239 -> 13984.148 | F20: ='[4]Shipments & Prices'!$O$25*1000 -> 32424.16 | G20: =IF(ISERROR((+H20/F20)*1000),0,(+H20/F20)*1000) -> 464.42371 | H20: ='[4]Shipments & Prices'!$O$239 -> 15058.549 | I20: =(F20-J20)*D20/1000 -> 885.6347 | J20: =$F$48*C20/$C$48 -> 30460.889 | L20: =(G20*$H$152)-(D20*$E$152) -> -31.991604 | M20: =L20*F20/1000/$E$152 -> -192.09276 | O20: =G20-D20 -> 13.32217 | P20: =O20*F20/1000 -> 431.96016 | Q20: =P20-M20 -> 624.05292 | R20: =R17/1000 -> -5.24787 | T20: =T18-C13 -> 1041.3076
B21: Plates DM | C21: ='[3]Shipments & Prices'!$O$28*1000 -> 18000 | D21: =IF(ISERROR((+E21/C21)*1000),0,(+E21/C21)*1000) -> 685.40017 | E21: ='[3]Shipments & Prices'!$O$242 -> 12337.203 | F21: ='[4]Shipments & Prices'!$O$28*1000 -> 16529.16 | G21: =IF(ISERROR((+H21/F21)*1000),0,(+H21/F21)*1000) -> 700.72228 | H21: ='[4]Shipments & Prices'!$O$242 -> 11582.351 | I21: =(F21-J21)*D21/1000 -> -793.56156 | J21: =$F$48*C21/$C$48 -> 17686.968 | L21: =(G21*$H$152)-(D21*$E$152) -> -74.072135 | M21: =L21*F21/1000/$E$152 -> -226.73151 | O21: =G21-D21 -> 15.32211 | P21: =O21*F21/1000 -> 253.26161 | Q21: =P21-M21 -> 479.99312 | AF21: Budget vs MRF10
B22: HRC Export | C22: ='[3]Shipments & Prices'!$O$30*1000 -> 433467 | D22: =IF(ISERROR((+E22/C22)*1000),0,(+E22/C22)*1000) -> 482.26451 | E22: ='[3]Shipments & Prices'!$O$244 -> 209045.75 | F22: ='[4]Shipments & Prices'!$O$30*1000 -> 197566.82 | G22: =IF(ISERROR((+H22/F22)*1000),0,(+H22/F22)*1000) -> 557.07307 | H22: ='[4]Shipments & Prices'!$O$244 -> 110059.16 | I22: =(F22-J22)*D22/1000 -> -110130.84 | J22: =$F$48*C22/$C$48 -> 425928.71 | K22: =G22-D22 -> 74.80856 | M22: =K22*F22/1000 -> 14779.689 | O22: =G22-D22 -> 74.80856 | P22: =O22*F22/1000 -> 14779.689 | Q22: =P22-M22 -> 0
B23: HRC DM Auto | C23: ='[3]Shipments & Prices'!$O$34*1000 -> 85817.96 | D23: =IF(ISERROR((+E23/C23)*1000),0,(+E23/C23)*1000) -> 681.44089 | E23: ='[3]Shipments & Prices'!$O$248 -> 58479.867 | F23: ='[4]Shipments & Prices'!$O$34*1000 -> 100236.84 | G23: =IF(ISERROR((+H23/F23)*1000),0,(+H23/F23)*1000) -> 725.82997 | H23: ='[4]Shipments & Prices'!$O$248 -> 72754.902 | I23: =(F23-J23)*D23/1000 -> 10842.62 | J23: =$F$48*C23/$C$48 -> 84325.527 | L23: =(G23*$H$152)-(D23*$E$152) -> 77.270714 | M23: =L23*F23/1000/$E$152 -> 1434.3282 | O23: =G23-D23 -> 44.38907 | P23: =O23*F23/1000 -> 4449.4202 | Q23: =P23-M23 -> 3015.092
B24: HRC DM Industry | C24: =('[3]Shipments & Prices'!$O$35)*1000 -> 1438681.3 | D24: =IF(ISERROR((+E24/C24)*1000),0,(+E24/C24)*1000) -> 658.77201 | E24: ='[3]Shipments & Prices'!$O$249 -> 947762.99 | F24: =('[4]Shipments & Prices'!$O$35)*1000 -> 1441770.7 | G24: =IF(ISERROR((+H24/F24)*1000),0,(+H24/F24)*1000) -> 693.84696 | H24: ='[4]Shipments & Prices'!$O$249 -> 1000368.2 | I24: =(F24-J24)*D24/1000 -> 18517.47 | J24: =$F$48*C24/$C$48 -> 1413661.7 | L24: =(G24*$H$152)-(D24*$E$152) -> 34.131787 | M24: =L24*F24/1000/$E$152 -> 9113.0022 | O24: =G24-D24 -> 35.074948 | P24: =O24*F24/1000 -> 50570.033 | Q24: =P24-M24 -> 41457.031 | R24: =C24+C25 -> 1866055.1 | S24: =(T24/R24)*1000 -> 680.92612 | T24: =E24+E25 -> 1270645.7
B25: HRC DM Downstream | C25: =+'[3]Shipments & Prices'!$O$36*1000 -> 427373.81 | D25: =IF(ISERROR((+E25/C25)*1000),0,(+E25/C25)*1000) -> 755.50415 | E25: =+'[3]Shipments & Prices'!$O$250 -> 322882.69 | F25: =+'[4]Shipments & Prices'!$O$36*1000 -> 446359.43 | G25: =IF(ISERROR((+H25/F25)*1000),0,(+H25/F25)*1000) -> 799.87146 | H25: ='[4]Shipments & Prices'!$O$250 -> 357030.17 | I25: =(F25-J25)*D25/1000 -> 19958.87 | J25: =$F$48*C25/$C$48 -> 419941.49 | L25: =(G25*$H$152)-(D25*$E$152) -> 60.583747 | M25: =L25*F25/1000/$E$152 -> 5007.8013 | O25: =G25-D25 -> 44.367302 | P25: =O25*F25/1000 -> 19803.764 | Q25: =P25-M25 -> 14795.962 | R25: =F24+F25 -> 1888130.2 | S25: =(T25/R25)*1000 -> 718.91146 | T25: =H24+H25 -> 1357398.4
B26: P&O DM Auto | C26: ='[3]Shipments & Prices'!$O$44*1000 -> 102999.19 | D26: =IF(ISERROR((+E26/C26)*1000),0,(+E26/C26)*1000) -> 859.20611 | E26: ='[3]Shipments & Prices'!$O$258 -> 88497.533 | F26: ='[4]Shipments & Prices'!$O$44*1000 -> 90523.858 | G26: =IF(ISERROR((+H26/F26)*1000),0,(+H26/F26)*1000) -> 914.47188 | H26: ='[4]Shipments & Prices'!$O$258 -> 82781.523 | I26: =(F26-J26)*D26/1000 -> -9179.8489 | J26: =$F$48*C26/$C$48 -> 101207.96 | L26: =(G26*$H$152)-(D26*$E$152) -> 93.789581 | M26: =L26*F26/1000/$E$152 -> 1572.2583 | O26: =G26-D26 -> 55.265775 | P26: =O26*F26/1000 -> 5002.8712 | Q26: =P26-M26 -> 3430.6129 | V26: =23/5.25 -> 4.3809524
B27: P&O DM Industry | C27: ='[3]Shipments & Prices'!$O$45*1000 -> 0 | D27: =G27 -> 723.2675 | E27: ='[3]Shipments & Prices'!$O$259 -> 0 | F27: ='[4]Shipments & Prices'!$O$45*1000 -> 45424.208 | G27: =IF(ISERROR((+H27/F27)*1000),0,(+H27/F27)*1000) -> 723.2675 | H27: ='[4]Shipments & Prices'!$O$259 -> 32853.853 | I27: =(F27-J27)*D27/1000 -> 32853.853 | J27: =$F$48*C27/$C$48 -> 0 | L27: =(G27*$H$152)-(D27*$E$152) -> -161.85682 | M27: =L27*F27/1000/$E$152 -> -1361.5219 | O27: =G27-D27 -> 0 | P27: =O27*F27/1000 -> 0 | Q27: =P27-M27 -> 1361.5219
B28: CRC EM Auto | C28: ='[3]Shipments & Prices'!$O$48*1000 -> 1220.3924 | D28: =IF(ISERROR((+E28/C28)*1000),0,(+E28/C28)*1000) -> 882.99234 | E28: ='[3]Shipments & Prices'!$O$262 -> 1077.5971 | F28: ='[4]Shipments & Prices'!$O$48*1000 -> 1887.8106 | G28: =IF(ISERROR((+H28/F28)*1000),0,(+H28/F28)*1000) -> 937.18709 | H28: ='[4]Shipments & Prices'!$O$262 -> 1769.2317 | I28: =(F28-J28)*D28/1000 -> 608.0653 | J28: =$F$48*C28/$C$48 -> 1199.1689 | L28: =(G28*$H$152)-(D28*$E$152) -> 82.922743 | M28: =L28*F28/1000/$E$152 -> 28.989339 | O28: =G28-D28 -> 54.194756 | P28: =O28*F28/1000 -> 102.30943 | Q28: =P28-M28 -> 73.320093
B29: CRC EM Industry | C29: ='[3]Shipments & Prices'!$O$49*1000 -> 492.26 | D29: =IF(ISERROR((+E29/C29)*1000),0,(+E29/C29)*1000) -> 323.31493 | E29: ='[3]Shipments & Prices'!$O$263 -> 159.15501 | F29: ='[4]Shipments & Prices'!$O$49*1000 -> 4847.375 | G29: =IF(ISERROR((+H29/F29)*1000),0,(+H29/F29)*1000) -> 603.52341 | H29: ='[4]Shipments & Prices'!$O$263 -> 2925.5043 | I29: =(F29-J29)*D29/1000 -> 1410.8415 | J29: =$F$48*C29/$C$48 -> 483.69926 | K29: =G29-D29 -> 280.20848 | M29: =K29*F29/1000 -> 1358.2756 | O29: =G29-D29 -> 280.20848 | P29: =O29*F29/1000 -> 1358.2756 | Q29: =P29-M29 -> 0
B30: CRC DM Auto | C30: ='[3]Shipments & Prices'!$O$51*1000 -> 90127.47 | D30: =IF(ISERROR((+E30/C30)*1000),0,(+E30/C30)*1000) -> 922.02223 | E30: ='[3]Shipments & Prices'!$O$265 -> 83099.531 | F30: ='[4]Shipments & Prices'!$O$51*1000 -> 95622.293 | G30: =IF(ISERROR((+H30/F30)*1000),0,(+H30/F30)*1000) -> 982.99579 | H30: ='[4]Shipments & Prices'!$O$265 -> 93996.312 | I30: =(F30-J30)*D30/1000 -> 6511.5067 | J30: =$F$48*C30/$C$48 -> 88560.092 | L30: =(G30*$H$152)-(D30*$E$152) -> 109.27698 | M30: =L30*F30/1000/$E$152 -> 1935.0584 | O30: =G30-D30 -> 60.973563 | P30: =O30*F30/1000 -> 5830.4319 | Q30: =P30-M30 -> 3895.3736
B31: CRC DM Industry | C31: =('[3]Shipments & Prices'!$O$52)*1000 -> 265325.54 | D31: =IF(ISERROR((+E31/C31)*1000),0,(+E31/C31)*1000) -> 788.21579 | E31: ='[3]Shipments & Prices'!$O$266 -> 209133.78 | F31: =('[4]Shipments & Prices'!$O$52)*1000 -> 286122.32 | G31: =IF(ISERROR((+H31/F31)*1000),0,(+H31/F31)*1000) -> 844.90554 | H31: ='[4]Shipments & Prices'!$O$266 -> 241746.33 | I31: =(F31-J31)*D31/1000 -> 20029.329 | J31: =$F$48*C31/$C$48 -> 260711.35 | L31: =(G31*$H$152)-(D31*$E$152) -> 117.04702 | M31: =L31*F31/1000/$E$152 -> 6201.8085 | O31: =G31-D31 -> 56.689756 | P31: =O31*F31/1000 -> 16220.205 | Q31: =P31-M31 -> 10018.396 | R31: =C31+C32 -> 375627.51 | S31: =(T31/R31)*1000 -> 801.51349 | T31: =E31+E32 -> 301070.52
B32: CRC DM Downstream | C32: =+'[3]Shipments & Prices'!$O$53*1000 -> 110301.97 | D32: =IF(ISERROR((+E32/C32)*1000),0,(+E32/C32)*1000) -> 833.50042 | E32: =+'[3]Shipments & Prices'!$O$267 -> 91936.738 | F32: =+'[4]Shipments & Prices'!$O$53*1000 -> 117390.91 | G32: =IF(ISERROR((+H32/F32)*1000),0,(+H32/F32)*1000) -> 892.1814 | H32: =+'[4]Shipments & Prices'!$O$267 -> 104733.99 | I32: =(F32-J32)*D32/1000 -> 7507.4783 | J32: =$F$48*C32/$C$48 -> 108383.74 | L32: =(G32*$H$152)-(D32*$E$152) -> 117.21996 | M32: =L32*F32/1000/$E$152 -> 2548.2515 | O32: =G32-D32 -> 58.680977 | P32: =O32*F32/1000 -> 6888.6133 | Q32: =P32-M32 -> 4340.3619 | R32: =F31+F32 -> 403513.23 | S32: =(T32/R32)*1000 -> 858.65913 | T32: =H31+H32 -> 346480.32
B33: HDG EM Auto | C33: ='[3]Shipments & Prices'!$O$61*1000 -> 49551.853 | D33: =IF(ISERROR((+E33/C33)*1000),0,(+E33/C33)*1000) -> 1018.0181 | E33: ='[3]Shipments & Prices'!$O$275 -> 50444.681 | F33: ='[4]Shipments & Prices'!$O$61*1000 -> 41148.524 | G33: =IF(ISERROR((+H33/F33)*1000),0,(+H33/F33)*1000) -> 1058.4157 | H33: ='[4]Shipments & Prices'!$O$275 -> 43552.244 | I33: =(F33-J33)*D33/1000 -> -7677.4736 | J33: =$F$48*C33/$C$48 -> 48690.112 | L33: =(G33*$H$152)-(D33*$E$152) -> -18.710747 | M33: =L33*F33/1000/$E$152 -> -142.57771 | O33: =G33-D33 -> 40.397668 | P33: =O33*F33/1000 -> 1662.3044 | Q33: =P33-M33 -> 1804.8821
B34: HDG EM Industry | C34: ='[3]Shipments & Prices'!$O$62*1000 -> 1014.12 | D34: =IF(ISERROR((+E34/C34)*1000),0,(+E34/C34)*1000) -> 323.31493 | E34: ='[3]Shipments & Prices'!$O$276 -> 327.88014 | F34: ='[4]Shipments & Prices'!$O$62*1000 -> 2599.121 | G34: =IF(ISERROR((+H34/F34)*1000),0,(+H34/F34)*1000) -> 562.09665 | H34: ='[4]Shipments & Prices'!$O$276 -> 1460.9572 | I34: =(F34-J34)*D34/1000 -> 518.15655 | J34: =$F$48*C34/$C$48 -> 996.48376 | K34: =G34-D34 -> 238.78171 | M34: =K34*F34/1000 -> 620.62257 | O34: =G34-D34 -> 238.78171 | P34: =O34*F34/1000 -> 620.62257 | Q34: =P34-M34 -> 0 | W34: =220-167 -> 53
B35: HDG DM Auto | C35: ='[3]Shipments & Prices'!$O$64*1000 -> 463694.03 | D35: =IF(ISERROR((+E35/C35)*1000),0,(+E35/C35)*1000) -> 1045.0986 | E35: ='[3]Shipments & Prices'!$O$278 -> 484605.99 | F35: ='[4]Shipments & Prices'!$O$64*1000 -> 463787.29 | G35: =IF(ISERROR((+H35/F35)*1000),0,(+H35/F35)*1000) -> 1098.849 | H35: ='[4]Shipments & Prices'!$O$278 -> 509632.21 | I35: =(F35-J35)*D35/1000 -> 8525.0978 | J35: =$F$48*C35/$C$48 -> 455630.07 | L35: =(G35*$H$152)-(D35*$E$152) -> 44.345684 | M35: =L35*F35/1000/$E$152 -> 3808.6971 | O35: =G35-D35 -> 53.750413 | P35: =O35*F35/1000 -> 24928.758 | Q35: =P35-M35 -> 21120.061
B36: HDG DM Industry | C36: =('[3]Shipments & Prices'!$O$65)*1000 -> 416584.71 | D36: =IF(ISERROR((+E36/C36)*1000),0,(+E36/C36)*1000) -> 848.78295 | E36: ='[3]Shipments & Prices'!$O$279 -> 353590 | F36: =('[4]Shipments & Prices'!$O$65)*1000 -> 438619.17 | G36: =IF(ISERROR((+H36/F36)*1000),0,(+H36/F36)*1000) -> 912.55186 | H36: ='[4]Shipments & Prices'!$O$279 -> 400262.74 | I36: =(F36-J36)*D36/1000 -> 24851.647 | J36: =$F$48*C36/$C$48 -> 409340.02 | L36: =(G36*$H$152)-(D36*$E$152) -> 140.13614 | M36: =L36*F36/1000/$E$152 -> 11382.666 | O36: =G36-D36 -> 63.768902 | P36: =O36*F36/1000 -> 27970.263 | Q36: =P36-M36 -> 16587.597 | R36: =C36+C37 -> 500124.04 | S36: =(T36/R36)*1000 -> 854.04782 | T36: =E36+E37 -> 427129.85
B37: HDG DM Downstream | C37: =+'[3]Shipments & Prices'!$O$66*1000 -> 83539.33 | D37: =IF(ISERROR((+E37/C37)*1000),0,(+E37/C37)*1000) -> 880.30207 | E37: =+'[3]Shipments & Prices'!$O$280 -> 73539.846 | F37: =+'[4]Shipments & Prices'!$O$66*1000 -> 76159.621 | G37: =IF(ISERROR((+H37/F37)*1000),0,(+H37/F37)*1000) -> 950.63961 | H37: =+'[4]Shipments & Prices'!$O$280 -> 72400.352 | I37: =(F37-J37)*D37/1000 -> -5217.4647 | J37: =$F$48*C37/$C$48 -> 82086.524 | L37: =(G37*$H$152)-(D37*$E$152) -> 167.08325 | M37: =L37*F37/1000/$E$152 -> 2356.481 | O37: =G37-D37 -> 70.337531 | P37: =O37*F37/1000 -> 5356.8797 | Q37: =P37-M37 -> 3000.3988 | R37: =F36+F37 -> 514778.79 | S37: =(T37/R37)*1000 -> 918.1868 | T37: =H36+H37 -> 472663.09
B38: AlZn Export | C38: ='[3]Shipments & Prices'!$O$74*1000 -> 0 | D38: =IF(ISERROR((+E38/C38)*1000),0,(+E38/C38)*1000) -> 0 | E38: ='[3]Shipments & Prices'!$O$288 -> 0 | F38: ='[4]Shipments & Prices'!$O$74*1000 -> 0 | G38: =IF(ISERROR((+H38/F38)*1000),0,(+H38/F38)*1000) -> 0 | H38: ='[4]Shipments & Prices'!$O$288 -> 0 | I38: =(F38-J38)*D38/1000 -> 0 | J38: =$F$48*C38/$C$48 -> 0 | K38: =G38-D38 -> 0 | M38: =K38*F38/1000 -> 0 | O38: =G38-D38 -> 0 | P38: =O38*F38/1000 -> 0 | Q38: =P38-M38 -> 0
B39: AlZn DM Industry | C39: =('[3]Shipments & Prices'!$O$79)*1000 -> 181457.09 | D39: =IF(ISERROR((+E39/C39)*1000),0,(+E39/C39)*1000) -> 973.02161 | E39: ='[3]Shipments & Prices'!$O$293 -> 176561.67 | F39: =('[4]Shipments & Prices'!$O$79)*1000 -> 136271.79 | G39: =IF(ISERROR((+H39/F39)*1000),0,(+H39/F39)*1000) -> 1027.641 | H39: ='[4]Shipments & Prices'!$O$293 -> 140038.48 | I39: =(F39-J39)*D39/1000 -> -40895.746 | J39: =$F$48*C39/$C$48 -> 178301.43 | L39: =(G39*$H$152)-(D39*$E$152) -> 64.973401 | M39: =L39*F39/1000/$E$152 -> 1639.6373 | O39: =G39-D39 -> 54.619373 | P39: =O39*F39/1000 -> 7443.0797 | Q39: =P39-M39 -> 5803.4424 | R39: =C39+C40 -> 287792.97 | S39: =(T39/R39)*1000 -> 1015.5456 | T39: =E39+E40 -> 292266.87
B40: ALZn DM Downstream | C40: =+'[3]Shipments & Prices'!$O$80*1000 -> 106335.88 | D40: =IF(ISERROR((+E40/C40)*1000),0,(+E40/C40)*1000) -> 1088.1106 | E40: =+'[3]Shipments & Prices'!$O$294 -> 115705.2 | F40: =+'[4]Shipments & Prices'!$O$80*1000 -> 88523.367 | G40: =IF(ISERROR((+H40/F40)*1000),0,(+H40/F40)*1000) -> 1184.3833 | H40: =+'[4]Shipments & Prices'!$O$294 -> 104845.6 | I40: =(F40-J40)*D40/1000 -> -17369.792 | J40: =$F$48*C40/$C$48 -> 104486.63 | L40: =(G40*$H$152)-(D40*$E$152) -> 254.82436 | M40: =L40*F40/1000/$E$152 -> 4177.3908 | O40: =G40-D40 -> 96.272637 | P40: =O40*F40/1000 -> 8522.378 | Q40: =P40-M40 -> 4344.9871 | R40: =F39+F40 -> 224795.16 | S40: =(T40/R40)*1000 -> 1089.3654 | T40: =H39+H40 -> 244884.07
...

Sheet Analise mes carvão
C1: Bridge | D1: Var. | E1: KD | G1: IP
B2: Budget vs MRF1 | C2: =[18]Box!$U$6+[18]Box!$U$7 -> -23.455538 | D2: =C2 -> -23.455538 | E2: =F14 -> -23.830202 | F2: =C2-E2 -> 0.37466398
B3: Budget vs MRF2 | C3: =([19]Cálculo!$J$116+[19]Cálculo!$J$117)/1000 -> -35.675657 | D3: =C3-C2 -> -12.220118 | E3: ='[20]Bridge FY'!$F$5 -> -12.315596 | F3: =D3-E3 -> 0.09547828
B4: Budget vs MRF3 | C4: =[21]Box!$U$6+[21]Box!$U$7 -> -38.600114 | D4: =C4-C3 -> -2.9244573 | E4: =L14 -> -3 | F4: =D4-E4 -> 0.075542655
B5: Budget vs MRF4 | C5: =[22]Box!$U$6+[22]Box!$U$7 -> -29.067403 | D5: =C5-C4 -> 9.5327109 | E5: =O14 -> 7.2991734 | F5: =D5-E5 -> 2.2335375
B6: Budget vs MRF5 | C6: =[23]Box!$U$6+[23]Box!$U$7 -> -30.958568 | D6: =C6-C5 -> -1.8911646 | E6: =R14 -> 0 | F6: =D6-E6 -> -1.8911646
B7: Budget vs MRF6 | C7: =Box!$U$6+Box!$U$7 -> -95.378798 | D7: =C7-C6 -> -64.42023 | E7: =U14 -> 1.6357735 | F7: =D7-E7 -> -66.056003
D8: =SUM(D2:D7) -> -95.378798 | E8: =SUM(E2:E7) -> -30.210852
E10: MRF1 | H10: MRF2 | K10: mrf3 | N10: mrf4 | Q10: mrf5
E11: Input Price | H11: Input Price | K11: Input Price | N11: Input Price | Q11: Input Price | T11: Input Price
E13: =A13 -> 0 | F13: =F15+F16+F17 -> -23.830202 | H13: Impact | I13: MUSD | K13: Impact | L13: MUSD | N13: =K13 -> Impact | O13: MUSD | Q13: Impact | R13: MUSD | T13: Impact | U13: MUSD
E14: Coal | F14: -23.830202 | H14: Coal | I14: -12.315596 | K14: Coal | L14: -3 | N14: Coal | O14: 7.2991734 | Q14: Coal | R14: 0 | T14: Coal | U14: 1.6357735
E15: International ref. | F15: -12.762719 | H15: Internacional reference | I15: -14.315596 | K15: Mix | L15: -5 | N15: International ref. | O15: 12 | Q15: International ref. | R15: 0 | T15: Price (may) | U15: 3
E16: Starting balance | F16: -13.216352 | H16: Mix/Others | I16: 2 | K16: Q2 PCI ratio | L16: 4 | N16: Q3 PCI ratio | O16: 5.3 | Q16: Mix | R16: 0 | T16: AMS contract updates | U16: 6
E17: Mix / others | F17: 2.148869 | H17: Purchased Coke | I17: -0.49931138 | K17: Demurrage | L17: -2 | N17: Freight | O17: -2 | Q17: Purchased Coke | R17: 0 | T17: (Price) PCI index | U17: -1.2956606
E18: Purchased Coke | F18: -5.9951706 | H18: Iron ore | I18: 6.3784712 | K18: Purchased Coke | L18: 0 | N18: Purchased Coke | O18: 2.5347094 | Q18: Iron ore | R18: -11.161322 | T18: Demurrage | U18: -3.0685658
E19: Iron ore | F19: -32.404121 | H19: Internacional reference | I19: 5.8423735 | K19: Iron ore | L19: 3.6635359 | N19: Mix | O19: -8 | Q19: International ref. | R19: -11.161322 | T19: Mix | U19: -3
E20: International ref. | F20: -17.602787 | H20: VIU premium (Si, Al & P) | I20: 2 | K20: International ref. | L20: 11.963352 | N20: Iron ore | O20: 59.494899 | Q20: Scrap | R20: 0 | T20: Purchased Coke | U20: 0.38990434
E21: Netback freight | F21: -5.5778136 | H21: % Fe | I21: -1.4639022 | K21: Pellet premium in Q2 | L21: -12.301144 | N21: International ref. | O21: 49.727698 | Q21: Alloys | R21: 0.13 | T21: Iron ore | U21: 2.2260463
E22: Pellet premium | F22: -9.2235212 | H22: Alloys | I22: -0.06 | K22: VIU Vale contract | L22: 4.4431404 | N22: Netback freight | O22: 17.634238 | Q22: Zinc (Vega) | R22: -1.47 | T22: International ref. | U22: -6.2737641
E23: Alloys | F23: -0.29 | H23: Zinc (Vega) | I23: 0.63 | K23: Alloys | L23: -0.27 | N23: Pellet premium | O23: -6.2029299 | Q23: Fluxes | R23: 0 | T23: Pellet premium | U23: 3.1816105
E24: Zinc (Vega) | F24: 0.86 | H24: Fluxes | I24: 0 | K24: Zinc (Vega) | L24: 0.79 | N24: VIU Vale contract | O24: -1.4641068 | Q24: Total | R24: -12.401322 | T24: Vale contract specification H2 | U24: 5.3182
E25: Fluxes | F25: 2 | H25: Total | I25: -5.8664365 | K25: Fluxes | L25: 3 | N25: Scrap | O25: 1.0073149 | T25: Scrap | U25: 0
E26: Total | F26: -59.659494 | K26: Total | L26: 4.1835359 | N26: Alloys | O26: 0.62 | T26: Alloys | U26: -2.35
N27: Zinc (Vega) | O27: 2.95 | T27: Zinc (Vega) | U27: 1.05
N28: Fluxes | O28: 0 | T28: Fluxes | U28: 1.32
N29: Total | O29: 73.906097 | T29: Total | U29: 4.2717242

Sheet Box
CD1: Consolidado | CG1: Pecém | CK1: Tuper
B2: Volume & Mix | I2: Selling price | P2: Input price | W2: Usage | Z2: Usage - Op. Performance | AC2: Usage - Market driven | AG2: Exchange rate | AO2: Logistic | AR2: Stock Variation/Others | AW2: Fixed cost | AZ2: Vale issues | BE2: AMS consolidation | BH2: For information only - Blacks & Reds | BQ2: For information only - Demurrage | BV2: FIO - Middle East War (Iran) | CA2: For information only - Forex | CD2: For information only - Forex | CG2: For information only - Forex | CK2: For information only - Forex | CN2: For information only - Middle East war
B4: Vol (kt) | C4: =J4 -> FY26'B | D4: =K4 -> FY26'F7 | E4: Var | F4: ="CM "&C4 -> CM FY26'B | G4: MUSD | I4: NRP $/t | J4: =Cálculo!D15 -> FY26'B | K4: =Cálculo!G15 -> FY26'F7 | L4: Var | M4: ="Vol "&K4 -> Vol FY26'F7 | N4: MUSD | P4: Price $/t | Q4: =J16 -> FY26'B | R4: =K16 -> FY26'F7 | S4: Var | T4: Yield | U4: MUSD | W4: Usage | X4: MUSD | Z4: Usage | AA4: MUSD | AC4: Usage | AD4: MUSD | AG4: Forex | AH4: =Cálculo!G15 -> FY26'F7 | AI4: % BRL | AK4: =Cálculo!G15 -> FY26'F7 | AL4: =Cálculo!D15 -> FY26'B | AM4: MUSD | AO4: Logistic | AP4: MUSD | AR4: Others | AS4: =AL4 -> FY26'B | AT4: =AK4 -> FY26'F7 | AU4: MUSD | AW4: Fixed cost | AX4: MUSD | AZ4: Vale issues | BA4: FY20 | BB4: FY21 | BC4: MUSD | BE4: =BE2 -> AMS consolidation | BF4: MUSD | BH4: Price $/t | BI4: FY26'B | BJ4: FY26'F7 | BK4: Var | BL4: kt | BM4: $m | BQ4: Demurrage | BR4: FY25B | BS4: FY25F | BT4: $m | BV4: Impact | BW4: MUSD | CA4: Impact | CB4: MUSD | CD4: Impact | CE4: MUSD | CG4: Impact | CH4: MUSD | CK4: Impact | CL4: MUSD | CN4: Impact | CO4: MUSD
B5: Slab Calvert | C5: =Cálculo!C17/1000 -> 961 | D5: =Cálculo!F17/1000 -> 966.24787 | E5: =D5-C5 -> 5.24787 | F5: =Cálculo!D83 -> 84.272668 | G5: =E5*F5/1000 -> 0.44225201 | H5: =Cálculo!P83/1000 -> 0.44225201 | I5: Slab Calvert | J5: =Cálculo!D17 -> 521.64672 | K5: =Cálculo!G17 -> 611.989 | L5: =K5-J5 -> 90.342283 | M5: =D5 -> 966.24787 | N5: =L5*M5/1000 -> 87.293039 | P5: Blacks | U5: =U6+U7+U9+U10 -> -91.531139 | W5: ='[10]Bridges complementares'!$E$5 -> Operational performance | X5: ='[10]Bridges complementares'!$F$5 -> -4.0925449 | Z5: =W5 -> Operational performance | AA5: =X5 -> -4.0925449 | AC5: =W16 -> Market driven | AD5: =X16 -> -8.7367984 | AG5: Sales Ind | AH5: =Cálculo!G150/1000 -> 5141.0891 | AI5: =AJ5/AH5 -> 0.47860693 | AJ5: =Cálculo!K13/1000 -> 2460.5609 | AK5: =Cálculo!H152 -> 5.1762144 | AL5: =Cálculo!E152 -> 5.4 | AM5: =Cálculo!Q10/1000 -> 104.08293 | AO5: Volume/mix | AP5: -3 | AR5: =Cálculo!B175 -> Invest-ES | AS5: =Cálculo!E175/1000 -> 134.78471 | AT5: =Cálculo!H175/1000 -> 129.88814 | AU5: =Cálculo!I175/1000 -> -4.896564 | AW5: =[8]FYB26xFYMRF7!$P$21 -> Controllable | AX5: =[8]FYB26xFYMRF7!$Q$21 -> -2.8984408 | AZ5: Vale issues | BA5: =#REF! -> #REF! | BB5: =#REF! -> #REF! | BH5: Coal (2 month lag) | BI5: ='[24]Coal lag_2months'!$O$3 -> 183.25 | BJ5: ='[24]Coal lag_2months'!$O$10 -> 231.6375 | BK5: =BJ5-BI5 -> 48.3875 | BL5: =SUM(Cálculo!I128)*Cálculo!G144 -> 2769.4034 | BM5: =-BK5*BL5/1000 -> -134.00451 | BQ5: Inbound | BR5: =BR6+BR7 -> 25 | BS5: =BS6+BS7 -> 19.7 | BT5: =BT6+BT7 -> 5.3 | BV5: Netback freight | BW5: 3 | CA5: =AG5 -> Sales Ind | CB5: =AM5 -> 104.08293 | CD5: =CA5 -> Sales Ind | CE5: =CB5+CL5 -> 106.28293 | CG5: =CD7 -> COGS | CH5: -23 | CK5: =CD5 -> Sales Ind | CL5: 2.2 | CN5: Slab sales | CO5: 17
B6: Slabs Others Intragroup | C6: =Cálculo!C18/1000 -> 400 | D6: =Cálculo!F18/1000 -> 997.32708 | E6: =D6-C6 -> 597.32708 | F6: =Cálculo!D84 -> 28.199955 | G6: =E6*F6/1000 -> 16.844597 | H6: =Cálculo!P84/1000 -> 16.844597 | I6: Slabs Others Intragroup | J6: =Cálculo!D18 -> 444.574 | K6: =Cálculo!G18 -> 516.61738 | L6: =K6-J6 -> 72.04338 | M6: =D6 -> 997.32708 | N6: =L6*M6/1000 -> 71.850814 | P6: Coal | Q6: =Cálculo!D128 -> 192.44908 | R6: =Cálculo!G128 -> 209.83033 | S6: =R6-Q6 -> 17.381256 | T6: =Cálculo!I128 -> 0.39731562 | U6: =-S6*T6*$U$23/1000 -> -48.13571 | V6: =(Cálculo!J128+Cálculo!J129)/1000 -> -95.378798 | W6: ='[10]Bridges complementares'!E6 -> Ironmaking | X6: ='[10]Bridges complementares'!F6 -> -3.3995496 | Z6: =W6 -> Ironmaking | AA6: =X6 -> -3.3995496 | AC6: =W17 -> Alloys | AD6: =X17 -> -6.5367984 | AG6: Sales Auto | AI6: =AJ6/AH5 -> 0.18090952 | AJ6: =Cálculo!K14/1000 -> 930.07195 | AM6: =Cálculo!Q11/1000 -> 39.317984 | AO6: Cabotage freight to south | AP6: -3 | AR6: Extraordinary effects | AS6: =AS7 -> 0 | AT6: =AT7 -> 0.14979323 | AU6: =AU7 -> 0.14979323 | AW6: =[8]FYB26xFYMRF7!$P$22 -> 2025 CLA | AX6: =[8]FYB26xFYMRF7!$Q$22 -> -3.7644492 | AZ6: Total | BC6: =BC5 -> 0 | BE6: Total | BF6: =SUM(BF5:BF5) -> 0 | BH6: FC Latam basket/mix/open balance | BM6: =BM11-SUM(BM7:BM10,BM5:BM5) -> 96.789906 | BQ6: Coal | BR6: 23 | BS6: 17.7 | BT6: =-BS6+BR6 -> 5.3 | BV6: Natural gas | BW6: =-(0.3+0.8) -> -1.1 | CA6: =AG6 -> Sales Auto | CB6: =AM6 -> 39.317984 | CD6: =CA6 -> Sales Auto | CE6: =CB6 -> 39.317984 | CG6: =CD8 -> Forex from inventories | CH6: -8 | CK6: Total | CL6: =SUM(CL5:CL6) -> 2 | CN6: Index cost | CO6: -131
B7: Slabs 3rd Party | C7: =Cálculo!C19/1000 -> 1423.1644 | D7: =Cálculo!F19/1000 -> 874.38504 | E7: =D7-C7 -> -548.77934 | F7: =Cálculo!D85 -> 36.906952 | G7: =E7*F7/1000 -> -20.253773 | H7: =Cálculo!P85/1000 -> 0 | I7: Slabs 3rd Party | J7: =Cálculo!D19 -> 453.281 | K7: =Cálculo!G19 -> 520.32299 | L7: =K7-J7 -> 67.04199 | M7: =D7 -> 874.38504 | N7: =L7*M7/1000 -> 58.620514 | P7: PCI | Q7: =Cálculo!D129 -> 193.47908 | R7: =Cálculo!G129 -> 218.48672 | S7: =R7-Q7 -> 25.007643 | T7: =Cálculo!I129 -> 0.27102848 | U7: =-S7*T7*$U$23/1000 -> -47.243088 | W7: ='[10]Bridges complementares'!E7 -> Steelmaking | X7: ='[10]Bridges complementares'!F7 -> -3 | Z7: =W7 -> Steelmaking | AA7: =X7 -> -3 | AC7: =W18 -> Coated lines | AD7: =X18 -> -2.2 | AG7: COGS | AH7: =Cálculo!G151/1000 -> -4393.3967 | AI7: =AJ7/AH7 -> 0.4 | AJ7: =Cálculo!H151/1000 -> -1757.3587 | AM7: =AJ7-(AJ7*AK5)/AL5 -> -72.828056 | AO7: Total | AP7: =AP5+AP6 -> -6 | AR7: =Cálculo!B160 -> Legal contingency | AS7: =Cálculo!E160/1000 -> 0 | AT7: =Cálculo!H160/1000 -> 0.14979323 | AU7: =(Cálculo!I160)/1000 -> 0.14979323 | AW7: =[8]FYB26xFYMRF7!$P$23 -> Publicity | AX7: =[8]FYB26xFYMRF7!$Q$23 -> 0.86600845 | BH7: Freight | BM7: =[9]FY_Budget!$AH$13 -> -7.3567876 | BQ7: Coke | BR7: 2 | BS7: 2 | BT7: =-BS7+BR7 -> 0 | BV7: Sales freight | BW7: -0.7 | CA7: =AG7 -> COGS | CB7: =AM7 -> -72.828056 | CD7: =CA7 -> COGS | CE7: =CB7+CH5 -> -95.828056 | CG7: Total | CH7: =SUM(CH5:CH6) -> -31 | CN7: Freight cost | CO7: 35
B8: HRC | C8: =Cálculo!C22/1000 -> 433.467 | D8: =Cálculo!F22/1000 -> 197.56682 | E8: =D8-C8 -> -235.90018 | F8: =Cálculo!D88 -> 36.052263 | G8: =E8*F8/1000 -> -8.5047354 | H8: =Cálculo!P88/1000 -> -8.5047354 | I8: HRC | J8: =Cálculo!D22 -> 482.26451 | K8: =Cálculo!G22 -> 557.07307 | L8: =K8-J8 -> 74.80856 | M8: =D8 -> 197.56682 | N8: =L8*M8/1000 -> 14.779689 | P8: Antracite | Q8: =Cálculo!D130 -> 0 | R8: =Cálculo!G130 -> 0 | S8: =R8-Q8 -> 0 | T8: =Cálculo!I130 -> 0 | U8: =-S8*T8*$U$23/1000 -> 0 | V8: =U6+U7 -> -95.378798 | W8: ='[10]Bridges complementares'!E8 -> Contractors | X8: ='[10]Bridges complementares'!F8 -> -2.4892741 | Z8: =W8 -> Contractors | AA8: =X8 -> -2.4892741 | AC8: Total | AD8: =AD5 -> -8.7367984 | AG8: Total | AM8: =SUM(AM5:AM7) -> 70.572859 | AR8: SV/Others | AU8: =Cálculo!C12-SUM(AU5:AU6) -> 0.30957452 | AW8: =[8]FYB26xFYMRF7!$P$24 -> Non-controllable | AX8: =[8]FYB26xFYMRF7!$Q$24 -> -5.4086265 | BH8: Demurrage | BM8: 3 | BQ8: Outbound | BR8: 3 | BS8: 1.88 | BT8: =-BS8+BR8 -> 1.12 | BV8: Total | BW8: =SUM(BW5:BW7) -> 1.2 | CA8: =AR10 -> Forex from inventories | CB8: =AU10 -> -20.388072 | CD8: =CA8 -> Forex from inventories | CE8: =CB8+CH6 -> -28.388072 | CN8: Total | CO8: =SUM(CO5:CO7) -> -79
B9: CRC Auto | C9: =Cálculo!C28/1000 -> 1.2203924 | D9: =Cálculo!F28/1000 -> 1.8878106 | E9: =D9-C9 -> 0.66741819 | F9: =Cálculo!D94 -> 388.26831 | G9: =E9*F9/1000 -> 0.25913734 | H9: =Cálculo!P94/1000 -> 0.25913734 | I9: CRC Auto | J9: =Cálculo!D28 -> 882.99234 | K9: =Cálculo!G28 -> 937.18709 | L9: =K9-J9 -> 54.194756 | M9: =D9 -> 1.8878106 | N9: =L9*M9/1000 -> 0.10230943 | P9: Coke | Q9: =Cálculo!D131 -> 312.92945 | R9: =Cálculo!G131 -> 340.61823 | S9: =R9-Q9 -> 27.688782 | T9: =Cálculo!I131 -> 0.014076067 | U9: =-S9*T9*$U$23/1000 -> -2.7166629 | V9: =V8-V6 -> 0 | W9: ='[10]Bridges complementares'!E9 -> Others | X9: ='[10]Bridges complementares'!F9 -> -1 | Z9: =W9 -> Others | AA9: =X9 -> -1 | AR9: =Cálculo!B168 -> Slowmoving | AS9: =Cálculo!E168/1000 -> 0 | AT9: =Cálculo!H168/1000 -> -2.6041187 | AU9: =Cálculo!H168/1000 -> -2.6041187 | AW9: =[8]FYB26xFYMRF7!$P$25 -> Pension Plan (Actuarial calculation) | AX9: =[8]FYB26xFYMRF7!$Q$25 -> -5.0981563 | BH9: PCI | BM9: =U7 -> -47.243088 | BQ9: Total | BR9: =BR5+BR8 -> 28 | BS9: =BS5+BS8 -> 21.58 | BT9: =BT8+BT5 -> 6.42 | CA9: Total | CB9: =SUM(CB5:CB8) -> 50.184787 | CD9: Total | CE9: =SUM(CE5:CE8) -> 21.384787
B10: CRC Ind | C10: =Cálculo!C29/1000 -> 0.49226 | D10: =Cálculo!F29/1000 -> 4.847375 | E10: =D10-C10 -> 4.355115 | F10: =Cálculo!D95 -> -171.40909 | G10: =E10*F10/1000 -> -0.7465063 | H10: =Cálculo!P95/1000 -> -0.7465063 | I10: CRC Ind | J10: =Cálculo!D29 -> 323.31493 | K10: =Cálculo!G29 -> 603.52341 | L10: =K10-J10 -> 280.20848 | M10: =D10 -> 4.847375 | N10: =L10*M10/1000 -> 1.3582756 | P10: AMS fee | Q10: =Cálculo!D132 -> 72.724806 | R10: =Cálculo!G132 -> 75.803894 | U10: =Cálculo!J137/1000 -> 6.5643217 | W10: ='[10]Bridges complementares'!E10 -> AMV | X10: ='[10]Bridges complementares'!F10 -> 5.7962788 | Z10: =W10 -> AMV | AA10: =X10 -> 5.7962788 | AR10: Forex from inventories | AU10: ='[25]Forex MRF 2026'!$EV$30 -> -20.388072 | AW10: =[8]FYB26xFYMRF7!$P$26 -> Insurance | AX10: =[8]FYB26xFYMRF7!$Q$26 -> 0.6895298 | BH10: Coke price | BM10: =U9-BT7 -> -2.7166629 | CN10: For information only - Middle East war
B11: HDG Auto | C11: =Cálculo!C33/1000 -> 49.551853 | D11: =Cálculo!F33/1000 -> 41.148524 | E11: =D11-C11 -> -8.4033296 | F11: =Cálculo!D99 -> 445.45556 | G11: =E11*F11/1000 -> -3.7433099 | H11: =Cálculo!P99/1000 -> -3.7433099 | I11: HDG Auto | J11: =Cálculo!D33 -> 1018.0181 | K11: =Cálculo!G33 -> 1058.4157 | L11: =K11-J11 -> 40.397668 | M11: =D11 -> 41.148524 | N11: =L11*M11/1000 -> 1.6623044 | P11: Reds | U11: =U12+U13+U14 -> -54.073371 | W11: ='[10]Bridges complementares'!E11 -> 0 | X11: ='[10]Bridges complementares'!F11 -> 0 | Z11: Total | AA11: =SUM(AA6:AA10) -> -4.0925449 | AK11: =AK5-AL5 -> -0.22378556 | AR11: Stock variation | AU11: =Cálculo!C12-SUM(AU5:AU6)-AU10-AU9 -> 23.301765 | AW11: =[8]FYB26xFYMRF7!$P$27 -> Others | AX11: =[8]FYB26xFYMRF7!$Q$27 -> -1 | BH11: Total | BM11: =U6+U7+U9+U10 -> -91.531139
B12: HDG Ind | C12: =Cálculo!C34/1000 -> 1.01412 | D12: =Cálculo!F34/1000 -> 2.599121 | E12: =D12-C12 -> 1.585001 | F12: =Cálculo!D100 -> -268.88972 | G12: =E12*F12/1000 -> -0.42619048 | H12: =Cálculo!P100/1000 -> -0.42619048 | I12: HDG Ind | J12: =Cálculo!D34 -> 323.31493 | K12: =Cálculo!G34 -> 562.09665 | L12: =K12-J12 -> 238.78171 | M12: =D12 -> 2.599121 | N12: =L12*M12/1000 -> 0.62062257 | P12: Fines | Q12: =Cálculo!D132 -> 72.724806 | R12: =Cálculo!G132 -> 75.803894 | S12: =R12-Q12 -> 3.079088 | T12: =Cálculo!I132 -> 0.50546148 | U12: =-S12*T12*$U$23/1000 -> -10.848277 | W12: ='[10]Bridges complementares'!E12 -> 0 | X12: ='[10]Bridges complementares'!F12 -> 0 | AM12: =AM7+'Bridge combinada'!J15 -> -95.358056 | AR12: Total | AU12: =AU5+AU6+AU8 -> -4.4371962 | AW12: =[8]FYB26xFYMRF7!$P$28 -> Value Creation | AX12: =[8]FYB26xFYMRF7!$Q$28 -> -25.047168 | CN12: Impact | CO12: MUSD
B13: AlZn Ind | C13: =Cálculo!C38/1000 -> 0 | D13: =Cálculo!F38/1000 -> 0 | E13: =D13-C13 -> 0 | F13: =Cálculo!D104 -> -663.85931 | G13: =E13*F13/1000 -> 0 | H13: =Cálculo!P104/1000 -> 0 | I13: AlZn Ind | J13: =Cálculo!D38 -> 0 | K13: =Cálculo!G38 -> 0 | L13: =K13-J13 -> 0 | M13: =D13 -> 0 | N13: =L13*M13/1000 -> 0 | P13: Pellets | Q13: =Cálculo!D133 -> 121.43893 | R13: =Cálculo!G133 -> 128.95793 | S13: =R13-Q13 -> 7.5189958 | T13: =Cálculo!I133 -> 0.7869986 | U13: =-S13*T13*$U$23/1000 -> -41.246241 | W13: ='[10]Bridges complementares'!E13 -> 0 | X13: ='[10]Bridges complementares'!F13 -> 0 | AW13: =[8]FYB26xFYMRF7!$P$29 -> 2026 PSP Complement | AX13: =[8]FYB26xFYMRF7!$Q$29 -> -14.275973 | BH13: =BH4 -> Price $/t | BI13: =BI4 -> FY26'B | BJ13: =BJ4 -> FY26'F7 | BK13: =BK4 -> Var | BL13: =BL4 -> kt | BM13: =BM4 -> $m | BO13: =BM11-SUM(BM5:BM10) -> 0 | CN13: Slab sales | CO13: 9
B14: Export | C14: =SUM(C5:C13) -> 3269.91 | D14: =SUM(D5:D13) -> 3086.0096 | E14: =SUM(E5:E13) -> -183.90036 | G14: =SUM(G5:G13) -> -16.128529 | H14: =SUM(H5:H13) -> 4.125244 | I14: Export | N14: =SUM(N5:N13) -> 236.28757 | P14: Lumps | Q14: =Cálculo!D134 -> 82.183924 | R14: =Cálculo!G134 -> 83.470247 | S14: =R14-Q14 -> 1.286323 | T14: =Cálculo!I134 -> 0.2207054 | U14: =-S14*T14*$U$23/1000 -> -1.9788532 | AM14: =AL5-AK5 -> 0.22378556 | AW14: =[8]FYB26xFYMRF7!$P$30 -> 2025 PSP Complement | AX14: =[8]FYB26xFYMRF7!$Q$30 -> -8.7711955 | BH14: Iron ore MB 62% (1m lag) | BI14: ='[26]Premissa - Budget 2026'!$U$7 -> 96.416667 | BJ14: ='[27]Premissa - MRF'!$U$7 -> 102.62247 | BK14: =BJ14-BI14 -> 6.2058 | BL14: =SUM(Cálculo!I132:I134)*Cálculo!G144-BL16-BM25 -> 4802.8657 | BM14: =-BK14*BL14/1000 -> -29.805624 | BQ14: For information only - Value Plan | CN14: Index cost | CO14: -100
P15: Alloys | U15: =Cálculo!$J$135/1000 -> -12.014339 | AM15: =AM14*AJ5 -> 550.63799 | AW15: =[8]FYB26xFYMRF7!$P$31 -> Partner remuneration | AX15: =[8]FYB26xFYMRF7!$Q$31 -> -1 | BH15: Iron ore MB 65% (1m lag) | BI15: ='[26]Premissa - Budget 2026'!$U$6 -> 109.41667 | BJ15: ='[27]Premissa - MRF'!$U$6 -> 116.54488 | BK15: =BJ15-BI15 -> 7.1282083 | BL15: =BL16+BM25 -> 5744.3299 | BM15: =-BK15*BL15/1000 -> -40.94678 | CN15: Freight cost | CO15: 31
B16: Vol (kt) | C16: =C4 -> FY26'B | D16: =D4 -> FY26'F7 | E16: Var | F16: =F4 -> CM FY26'B | G16: MUSD | I16: NRP $/t | J16: =J4 -> FY26'B | K16: =K4 -> FY26'F7 | L16: Var | M16: =M4 -> Vol FY26'F7 | N16: MUSD | P16: Others | U16: =SUM(U17:U20) -> -19.853098 | W16: ='[10]Bridges complementares'!$E$14 -> Market driven | X16: ='[10]Bridges complementares'!$F$14 -> -8.7367984 | AM16: =AM15/AL5 -> 101.97 | AW16: =[8]FYB26xFYMRF7!$P$32 -> HVA Growth | AX16: =[8]FYB26xFYMRF7!$Q$32 -> -1 | BH16: Pellet premium | BI16: ='[26]Premissa - Budget 2026'!$U$9 -> 30 | BJ16: ='[27]Premissa - MRF'!$U$9+3 -> 36.5 | BK16: =BJ16-BI16 -> 6.5 | BL16: =Cálculo!I133*Cálculo!G144 -> 5485.605 | BM16: =-BK16*BL16/1000 -> -35.656433 | BQ16: Value plan | BR16: FY23B | BS16: FY23F | BT16: $m | CN16: Total | CO16: =SUM(CO13:CO15) -> -60
B17: Slab | C17: =Cálculo!C20/1000 -> 31 | D17: =Cálculo!F20/1000 -> 32.42416 | E17: =D17-C17 -> 1.42416 | F17: =Cálculo!D86 -> 0.72748999 | G17: =E17*F17/1000 -> 0.0010360621 | I17: Slab | J17: =Cálculo!D20*Cálculo!$E$152 -> 2435.9483 | K17: =Cálculo!G20*Cálculo!$H$152 -> 2403.9567 | L17: =K17-J17 -> -31.991604 | M17: =D17 -> 32.42416 | N17: =L17*M17/1000/$N$40 -> -0.19209276 | P17: Natural gas | U17: =Cálculo!J138/1000 -> 0.20690204 | W17: ='[10]Bridges complementares'!$E$15 -> Alloys | X17: ='[10]Bridges complementares'!$F$15 -> -6.5367984 | AW17: =[8]FYB26xFYMRF7!$P$33 -> Total | AX17: =AX12+AX8+AX5-1 -> -34.354236 | BH17: Rebate (pellet premium) | BI17: 0 | BJ17: -3 | BK17: =BJ17-BI17 -> -3 | BL17: =BL16 -> 5485.605 | BM17: =-BK17*BL17/1000 -> 16.456815 | BQ17: Usage & Mix | BR17: 28 | BS17: 11 | BT17: =BS17-BR17 -> -17
B18: Plates | C18: =Cálculo!C21/1000 -> 18 | D18: =Cálculo!F21/1000 -> 16.52916 | E18: =D18-C18 -> -1.47084 | F18: =Cálculo!D87 -> 269.02612 | G18: =E18*F18/1000 -> -0.39569438 | I18: Plates | J18: =Cálculo!D21*Cálculo!$E$152 -> 3701.1609 | K18: =Cálculo!G21*Cálculo!$H$152 -> 3627.0888 | L18: =K18-J18 -> -74.072135 | M18: =D18 -> 16.52916 | N18: =L18*M18/1000/$N$40 -> -0.22673151 | P18: Zinc | U18: =Cálculo!$J$136/1000 -> -11.03 | W18: ='[10]Bridges complementares'!$E$16 -> Coated lines | X18: ='[10]Bridges complementares'!$F$16 -> -2.2 | AM18: -60.00925 | AO18: =AM5-AM18 -> 164.09218 | BH18: Lump premium | BI18: ='[26]Premissa - Budget 2026'!$U$10 -> 8.2766667 | BJ18: ='[27]Premissa - MRF'!$U$10 -> 6.6041667 | BK18: =BJ18-BI18 -> -1.6725 | BL18: =Cálculo!I134*Cálculo!G144 -> 1538.3797 | BM18: =-BK18*BL18/1000 -> 2.57294 | BQ18: Volume | BR18: 4 | BS18: 16 | BT18: =BS18-BR18 -> 12
B19: HRC Auto | C19: =Cálculo!C23/1000 -> 85.81796 | D19: =Cálculo!F23/1000 -> 100.23684 | E19: =D19-C19 -> 14.41888 | F19: =Cálculo!D89 -> 244.22864 | G19: =E19*F19/1000 -> 3.5215036 | I19: HRC Auto | J19: =Cálculo!D23*Cálculo!$E$152 -> 3679.7808 | K19: =Cálculo!G23*Cálculo!$H$152 -> 3757.0515 | L19: =K19-J19 -> 77.270714 | M19: =D19 -> 100.23684 | N19: =L19*M19/1000/$N$40 -> 1.4343282 | P19: Fluxes | U19: =Cálculo!J139/1000 -> -7.03 | W19: ='[10]Bridges complementares'!$E$17 -> Total | X19: =X16+X5 -> -12.829343 | Z19: =U21+X19 -> -190.30129 | AM19: -21.124353 | AO19: =AM6-AM19 -> 60.442337 | BH19: Netback freight | BI19: ='[26]Premissa - Budget 2026'!$U$8 -> 15.957103 | BJ19: ='[27]Premissa - MRF'!$U$8 -> 19.879362 | BK19: =BJ19-BI19 -> 3.9222589 | BL19: =SUM(BL14:BL15) -> 10547.196 | BM19: =BK19*BL19/1000 -> 41.368831 | BQ19: Input price | BR19: 2 | BS19: 15 | BT19: =BS19-BR19 -> 13
B20: HRC Ind | C20: =Cálculo!C24/1000 -> 1438.6813 | D20: =Cálculo!F24/1000 -> 1441.7707 | E20: =D20-C20 -> 3.089416 | F20: =Cálculo!D90 -> 221.55976 | G20: =E20*F20/1000 -> 0.68449027 | I20: HRC Ind | J20: =Cálculo!D24*Cálculo!$E$152 -> 3557.3689 | K20: =Cálculo!G24*Cálculo!$H$152 -> 3591.5007 | L20: =K20-J20 -> 34.131787 | M20: =D20 -> 1441.7707 | N20: =L20*M20/1000/$N$40 -> 9.1130022 | P20: Energy | U20: =Cálculo!J140/1000 -> -2 | Z20: =X18+X8+X9+U10+U17+U18 -> -9.9480504 | AM20: 39.81089 | AO20: =AM7-AM20 -> -112.63895 | BH20: Forex (contract) | BM20: =([28]FY!$AF$11+[28]FY!$AI$11)/1000 -> -5.8272357 | BQ20: Sales mix | BR20: 3 | BS20: 3 | BT20: =BS20-BR20 -> 0
B21: HRC Down | C21: =Cálculo!C25/1000 -> 427.37381 | D21: =Cálculo!F25/1000 -> 446.35943 | E21: =D21-C21 -> 18.985624 | F21: =Cálculo!D91 -> 238.2919 | G21: =E21*F21/1000 -> 4.5241206 | I21: HRC Down | J21: =Cálculo!D25*Cálculo!$E$152 -> 4079.7224 | K21: =Cálculo!G25*Cálculo!$H$152 -> 4140.3062 | L21: =K21-J21 -> 60.583747 | M21: =D21 -> 446.35943 | N21: =L21*M21/1000/$N$40 -> 5.0078013 | P21: Total | U21: =SUM(U5,U11,U15,U16) -> -177.47195 | Z21: =Z19-Z20 -> -180.35324 | AM21: -41.322712 | AO21: =AM8-AM21 -> 111.89557 | BH21: Others (Vale contract specification, VIU, open balance) | BM21: =-(SUM(BM14:BM20)-BM22) -> -2.2358845 | BQ21: Selling price | BR21: 0 | BS21: 3 | BT21: =BS21-BR21 -> 3
B22: P&O Auto | C22: =Cálculo!C26/1000 -> 102.99919 | D22: =Cálculo!F26/1000 -> 90.523858 | E22: =D22-C22 -> -12.475332 | F22: =Cálculo!D92 -> 341.99386 | G22: =E22*F22/1000 -> -4.266487 | I22: P&O Auto | J22: =Cálculo!D26*Cálculo!$E$152 -> 4639.713 | K22: =Cálculo!G26*Cálculo!$H$152 -> 4733.5026 | L22: =K22-J22 -> 93.789581 | M22: =D22 -> 90.523858 | N22: =L22*M22/1000/$N$40 -> 1.5722583 | W22: TOTAL | X22: =U21+X19 -> -190.30129 | Z22: =U21+X19-X18-U18-U17-U10-X8-X9 -> -180.35324 | BH22: Total | BM22: =SUM(U12:U14) -> -54.073371 | BO22: =BM22-SUM(BM14:BM21) -> 0 | BQ22: Non steel | BR22: 0 | BS22: 1 | BT22: =BS22-BR22 -> 1
B23: P&O Ind | C23: =Cálculo!C27/1000 -> 0 | D23: =Cálculo!F27/1000 -> 45.424208 | E23: =D23-C23 -> 45.424208 | F23: =Cálculo!D93 -> 269.38858 | G23: =E23*F23/1000 -> 12.236763 | I23: P&O Ind | J23: =Cálculo!D27*Cálculo!$E$152 -> 3905.6445 | K23: =Cálculo!G27*Cálculo!$H$152 -> 3743.7877 | L23: =K23-J23 -> -161.85682 | M23: =D23 -> 45.424208 | N23: =L23*M23/1000/$N$40 -> -1.3615219 | P23: Crude Steel (kt) | U23: =Cálculo!G144 -> 6970.2857 | W23: VeGa | X23: =X17+X12+U17+U18 -> -17.359896 | Y23: 9 | BQ23: Total | BR23: 38 | BS23: 50 | BT23: =SUM(BT17:BT22) -> 12
B24: CRC Auto | C24: =Cálculo!C30/1000 -> 90.12747 | D24: =Cálculo!F30/1000 -> 95.622293 | E24: =D24-C24 -> 5.4948228 | F24: =Cálculo!D96 -> 427.2982 | G24: =E24*F24/1000 -> 2.3479279 | I24: CRC Auto | J24: =Cálculo!D30*Cálculo!$E$152 -> 4978.92 | K24: =Cálculo!G30*Cálculo!$H$152 -> 5088.197 | L24: =K24-J24 -> 109.27698 | M24: =D24 -> 95.622293 | N24: =L24*M24/1000/$N$40 -> 1.9350584 | P24: Check | Q24: = | U24: =Cálculo!C9 -> -177.47195 | W24: SUBTOTAL | X24: =X22-X23 -> -172.94139 | AU24: =#REF!+#REF!+#REF! -> #REF! | AW24: =Box!#REF!+Box!AU7+Box!#REF!+Box!#REF! -> #REF!
B25: CRC Ind | C25: =Cálculo!C31/1000 -> 265.32554 | D25: =Cálculo!F31/1000 -> 286.12232 | E25: =D25-C25 -> 20.796778 | F25: =Cálculo!D97 -> 293.49176 | G25: =E25*F25/1000 -> 6.1036832 | I25: CRC Ind | J25: =Cálculo!D31*Cálculo!$E$152 -> 4256.3653 | K25: =Cálculo!G31*Cálculo!$H$152 -> 4373.4123 | L25: =K25-J25 -> 117.04702 | M25: =D25 -> 286.12232 | N25: =L25*M25/1000/$N$40 -> 6.2018085 | U25: =U24-U21 -> 0 | W25: Minério foex | X25: -10 | BM25: ='[27]Iron ore - Calculo 2026'!$J$127+'[27]Iron ore - Calculo 2026'!$K$127 -> 258.72488
B26: CRC Down | C26: =Cálculo!C32/1000 -> 110.30197 | D26: =Cálculo!F32/1000 -> 117.39091 | E26: =D26-C26 -> 7.088941 | F26: =Cálculo!D98 -> 258.7764 | G26: =E26*F26/1000 -> 1.8344506 | I26: CRC Down | J26: =Cálculo!D32*Cálculo!$E$152 -> 4500.9023 | K26: =Cálculo!G32*Cálculo!$H$152 -> 4618.1222 | L26: =K26-J26 -> 117.21996 | M26: =D26 -> 117.39091 | N26: =L26*M26/1000/$N$40 -> 2.5482515 | W26: SUBTOTAL2 | X26: =X24+X25 -> -182.94139
B27: HDG Auto | C27: =Cálculo!C35/1000 -> 463.69403 | D27: =Cálculo!F35/1000 -> 463.78729 | E27: =D27-C27 -> 0.093261061 | F27: =Cálculo!D101 -> 472.53611 | G27: =E27*F27/1000 -> 0.044069219 | I27: HDG Auto | J27: =Cálculo!D35*Cálculo!$E$152 -> 5643.5325 | K27: =Cálculo!G35*Cálculo!$H$152 -> 5687.8782 | L27: =K27-J27 -> 44.345684 | M27: =D27 -> 463.78729 | N27: =L27*M27/1000/$N$40 -> 3.8086971 | W27: sv BD | X27: =-[29]FY25BxFY25A!$P$45/1000000 -> -30.880903 | AO27: =Box!#REF!+Box!AU7+Box!#REF!+Box!#REF!+Box!#REF!+Box!#REF! -> #REF!
B28: HDG Ind | C28: =Cálculo!C36/1000 -> 416.58471 | D28: =Cálculo!F36/1000 -> 438.61917 | E28: =D28-C28 -> 22.03446 | F28: =Cálculo!D102 -> 256.5783 | G28: =E28*F28/1000 -> 5.6535642 | I28: HDG Ind | J28: =Cálculo!D36*Cálculo!$E$152 -> 4583.428 | K28: =Cálculo!G36*Cálculo!$H$152 -> 4723.5641 | L28: =K28-J28 -> 140.13614 | M28: =D28 -> 438.61917 | N28: =L28*M28/1000/$N$40 -> 11.382666 | W28: Var. HRC | X28: 4
B29: HDG Down | C29: =Cálculo!C37/1000 -> 83.53933 | D29: =Cálculo!F37/1000 -> 76.159621 | E29: =D29-C29 -> -7.3797089 | F29: =Cálculo!D103 -> 208.09742 | G29: =E29*F29/1000 -> -1.5356984 | I29: HDG Down | J29: =Cálculo!D37*Cálculo!$E$152 -> 4753.6312 | K29: =Cálculo!G37*Cálculo!$H$152 -> 4920.7145 | L29: =K29-J29 -> 167.08325 | M29: =D29 -> 76.159621 | N29: =L29*M29/1000/$N$40 -> 2.356481 | R29: = | W29: TOTAL | X29: =X26+X27-X28 -> -217.8223
B30: AlZn Ind | C30: =Cálculo!C39/1000 -> 181.45709 | D30: =Cálculo!F39/1000 -> 136.27179 | E30: =D30-C30 -> -45.185301 | F30: =Cálculo!D105 -> 309.1623 | G30: =E30*F30/1000 -> -13.969592 | I30: AlZn Ind | J30: =Cálculo!D39*Cálculo!$E$152 -> 5254.3167 | K30: =Cálculo!G39*Cálculo!$H$152 -> 5319.2901 | L30: =K30-J30 -> 64.973401 | M30: =D30 -> 136.27179 | N30: =L30*M30/1000/$N$40 -> 1.6396373 | BH30: ∆ | BM30: =BM21-BM27-BM28 -> -2.2358845
B31: AlZn Down | C31: =Cálculo!C40/1000 -> 106.33588 | D31: =Cálculo!F40/1000 -> 88.523367 | E31: =D31-C31 -> -17.812513 | F31: =Cálculo!D106 -> 344.25133 | G31: =E31*F31/1000 -> -6.1319814 | I31: AlZn Down | J31: =Cálculo!D40*Cálculo!$E$152 -> 5875.7975 | K31: =Cálculo!G40*Cálculo!$H$152 -> 6130.6218 | L31: =K31-J31 -> 254.82436 | M31: =D31 -> 88.523367 | N31: =L31*M31/1000/$N$40 -> 4.1773908 | W31: EBITDA COST | X31: =-'[30]Máscara (Divulgação)'!$BD$20/1000 -> -29.259862
B32: Usibor Auto | C32: =Cálculo!C41/1000 -> 94.231595 | D32: =Cálculo!F41/1000 -> 99.323021 | E32: =D32-C32 -> 5.0914261 | F32: =Cálculo!D107 -> 718.52838 | G32: =E32*F32/1000 -> 3.6583342 | I32: Usibor Auto | J32: =Cálculo!D41*Cálculo!$E$152 -> 6973.4038 | K32: =Cálculo!G41*Cálculo!$H$152 -> 7149.6531 | L32: =K32-J32 -> 176.24927 | M32: =D32 -> 99.323021 | N32: =L32*M32/1000/$N$40 -> 3.2417797
B33: AlSi Ind | C33: =Cálculo!C42/1000 -> 7.73754 | D33: =Cálculo!F42/1000 -> 7.661225 | E33: =D33-C33 -> -0.076315 | F33: =Cálculo!D108 -> 275.87627 | G33: =E33*F33/1000 -> -0.021053497 | I33: AlSi Ind | J33: =Cálculo!D42*Cálculo!$E$152 -> 4583.0824 | K33: =Cálculo!G42*Cálculo!$H$152 -> 4243.7619 | L33: =K33-J33 -> -339.32045 | M33: =D33 -> 7.661225 | N33: =L33*M33/1000/$N$40 -> -0.48140931 | X33: =X29-X31 -> -188.56244
B34: Auto imp | C34: =Cálculo!C43/1000 -> 3.8163262 | D34: =Cálculo!F43/1000 -> 3.6272929 | E34: =D34-C34 -> -0.18903329 | F34: =Cálculo!D109 -> 1208.6234 | G34: =E34*F34/1000 -> -0.22847005 | I34: Auto imp | J34: =Cálculo!D43*Cálculo!$E$152 -> 10111.406 | K34: =Cálculo!G43*Cálculo!$H$152 -> 10097.65 | L34: =K34-J34 -> -13.756064 | M34: =D34 -> 3.6272929 | N34: =L34*M34/1000/$N$40 -> -0.0092402355
B35: =Cálculo!B45 -> Industry Imports | C35: =Cálculo!C45/1000 -> 35.39997 | D35: =Cálculo!F45/1000 -> 17.169268 | E35: =D35-C35 -> -18.230702 | F35: =Cálculo!D111 -> 284.85966 | G35: =E35*F35/1000 -> -5.1931916 | I35: =B35 -> Industry Imports | J35: =Cálculo!D45*Cálculo!$E$152 -> 5123.0825 | K35: =Cálculo!G45*Cálculo!$H$152 -> 5212.3443 | L35: =K35-J35 -> 89.261878 | M35: =D35 -> 17.169268 | N35: =L35*M35/1000/$N$40 -> 0.28380761
B36: =Cálculo!B46 -> Magnelis DM Downstream | C36: =Cálculo!C46/1000 -> 0 | D36: =Cálculo!F46/1000 -> 7.00288 | E36: =D36-C36 -> 7.00288 | F36: =Cálculo!D112 -> 343.65894 | G36: =E36*F36/1000 -> 2.4066023 | I36: =B36 -> Magnelis DM Downstream | J36: =Cálculo!D46*Cálculo!$E$152 -> 5440.5986 | K36: =Cálculo!G46*Cálculo!$H$152 -> 5215.1305 | L36: =K36-J36 -> -225.46804 | M36: =D36 -> 7.00288 | N36: =L36*M36/1000/$N$40 -> -0.29239363
B37: =Cálculo!B47 -> HRC Aperam baixo carbono | C37: =Cálculo!C47/1000 -> 0 | D37: =Cálculo!F47/1000 -> 0 | E37: =D37-C37 -> 0 | F37: =Cálculo!D113 -> 30 | G37: =E37*F37/1000 -> 0 | I37: =B37 -> HRC Aperam baixo carbono | J37: =Cálculo!D47*Cálculo!$E$152 -> 0 | K37: =Cálculo!G47*Cálculo!$H$152 -> 0 | L37: =K37-J37 -> 0 | M37: =D37 -> 0 | N37: =L37*M37/1000/$N$40 -> 0 | BQ37: TVC
B38: Revenue recognition | G38: =Cálculo!I166/1000 -> 0 | I38: Domestic | N38: =SUM(N17:N37) -> 52.139579 | BQ38: For information only - Trade defense
B39: Domestic | C39: =SUM(C17:C38) -> 3962.4237 | D39: =SUM(D17:D38) -> 4010.5488 | E39: =SUM(E17:E38) -> 48.125113 | G39: =SUM(G17:G38) -> 11.274377
I40: Forex | N40: =Cálculo!$E$152 -> 5.4 | BQ40: Trade defense | BR40: FY26B | BS40: FY26F | BT40: $m
BQ41: Volume & mix | BR41: 46.8 | BS41: =41-BS52 -> 38.5 | BT41: =BS41-BR41 -> -8.3
...

Sheet Box (resumo sem AMD)
B2: Volume & Mix | I2: Selling price | P2: Input price | W2: Usage | Z2: Fixed cost | AF2: Forex on costs | AN2: Others | AQ2: Non recurrent & Legal/compliance | AV2: Fixed cost | AY2: Vale negotiation | BD2: AMS consolidation | BG2: For information only - Flat raw material basket | BQ2: Calvert impact | BV2: Mandatory | CA2: Inflation | CD2: Footprint | CG2: Usage
B4: Vol (kt) | C4: =J4 -> FY26'B | D4: =K4 -> FY26'F7 | E4: Var | F4: ="CM "&C4 -> CM FY26'B | G4: MUSD | I4: NRP $/t | J4: =Cálculo!D15 -> FY26'B | K4: =Cálculo!G15 -> FY26'F7 | L4: Var | M4: ="Vol "&K4 -> Vol FY26'F7 | N4: MUSD
B5: Slab Calvert | C5: =Cálculo!C17/1000 -> 961 | D5: =Cálculo!F17/1000 -> 966.24787 | E5: =D5-C5 -> 5.24787 | F5: =Cálculo!D83 -> 84.272668 | G5: =E5*F5/1000 -> 0.44225201 | H5: =G5-Box!G5 -> 0 | I5: Slab Calvert | J5: =Cálculo!D17 -> 521.64672 | K5: =Cálculo!G17 -> 611.989 | L5: =K5-J5 -> 90.342283 | M5: =Box!M5 -> 966.24787 | N5: =L5*M5/1000 -> 87.293039 | O5: =Cálculo!M17 -> 87293.039 | DF5: =O5/1000 -> 87.293039
B6: Slabs Others Intragroup | C6: =Cálculo!C18/1000 -> 400 | D6: =Cálculo!F18/1000 -> 997.32708 | E6: =D6-C6 -> 597.32708 | F6: =Cálculo!D84 -> 28.199955 | G6: =E6*F6/1000 -> 16.844597 | I6: Slabs Others Intragroup | J6: =Cálculo!D18 -> 444.574 | K6: =Cálculo!G18 -> 516.61738 | L6: =K6-J6 -> 72.04338 | M6: =Box!M6 -> 997.32708 | N6: =L6*M6/1000 -> 71.850814 | O6: =Cálculo!M18 -> 71850.814 | DF6: =O6/1000 -> 71.850814
B7: Slabs 3rd Party | C7: =Cálculo!C19/1000 -> 1423.1644 | D7: =Cálculo!F19/1000 -> 874.38504 | E7: =D7-C7 -> -548.77934 | F7: =Cálculo!D85 -> 36.906952 | G7: =E7*F7/1000 -> -20.253773 | I7: Slabs 3rd Party | J7: =Cálculo!D19 -> 453.281 | K7: =Cálculo!G19 -> 520.32299 | L7: =K7-J7 -> 67.04199 | M7: =Box!M7 -> 874.38504 | N7: =L7*M7/1000 -> 58.620514
B8: HRC | C8: =Cálculo!C22/1000 -> 433.467 | D8: =Cálculo!F22/1000 -> 197.56682 | E8: =D8-C8 -> -235.90018 | F8: =Cálculo!D88 -> 36.052263 | G8: =E8*F8/1000 -> -8.5047354 | I8: HRC | J8: =Cálculo!D22 -> 482.26451 | K8: =Cálculo!G22 -> 557.07307 | L8: =K8-J8 -> 74.80856 | M8: =Box!M8 -> 197.56682 | N8: =L8*M8/1000 -> 14.779689 | DF8: =O8/1000 -> 0
B9: CRC Auto | C9: =Cálculo!C28/1000 -> 1.2203924 | D9: =Cálculo!F28/1000 -> 1.8878106 | E9: =D9-C9 -> 0.66741819 | F9: =Cálculo!D94 -> 388.26831 | G9: =E9*F9/1000 -> 0.25913734 | I9: CRC Auto | J9: =Cálculo!D28*Cálculo!$E$152 -> 4768.1586 | K9: =Cálculo!G28*Cálculo!$H$152 -> 4851.0814 | L9: =K9-J9 -> 82.922743 | M9: =D9 -> 1.8878106 | N9: =L9*M9/1000/$N$38 -> 0.028989339 | DF9: =O9/1000 -> 0
B10: CRC Ind | C10: =Cálculo!C29/1000 -> 0.49226 | D10: =Cálculo!F29/1000 -> 4.847375 | E10: =D10-C10 -> 4.355115 | F10: =Cálculo!D95 -> -171.40909 | G10: =E10*F10/1000 -> -0.7465063 | I10: CRC Ind | J10: =Cálculo!D29 -> 323.31493 | K10: =Cálculo!G29 -> 603.52341 | L10: =K10-J10 -> 280.20848 | M10: =D10 -> 4.847375 | N10: =L10*M10/1000 -> 1.3582756 | DF10: =O10/1000 -> 0
B11: HDG Auto | C11: =Cálculo!C33/1000 -> 49.551853 | D11: =Cálculo!F33/1000 -> 41.148524 | E11: =D11-C11 -> -8.4033296 | F11: =Cálculo!D99 -> 445.45556 | G11: =E11*F11/1000 -> -3.7433099 | I11: HDG Auto | J11: =Cálculo!D33*Cálculo!$E$152 -> 5497.2975 | K11: =Cálculo!G33*Cálculo!$H$152 -> 5478.5868 | L11: =K11-J11 -> -18.710747 | M11: =D11 -> 41.148524 | N11: =L11*M11/1000/$N$38 -> -0.14257771 | DF11: =O11/1000 -> 0
B12: HDG Ind | C12: =Cálculo!C34/1000 -> 1.01412 | D12: =Cálculo!F34/1000 -> 2.599121 | E12: =D12-C12 -> 1.585001 | F12: =Cálculo!D100 -> -268.88972 | G12: =E12*F12/1000 -> -0.42619048 | I12: HDG Ind | J12: =Cálculo!D34 -> 323.31493 | K12: =Cálculo!G34 -> 562.09665 | L12: =K12-J12 -> 238.78171 | M12: =D12 -> 2.599121 | N12: =L12*M12/1000 -> 0.62062257 | DF12: =O12/1000 -> 0 | DG12: ='Box (resumo sem AMD)'!C14+'Box (resumo sem AMD)'!C12+'Box (resumo sem AMD)'!C10 -> 1.50638
B13: =Cálculo!B44 -> Magnelis DM Industry | C13: =Cálculo!C44/1000 -> 0 | D13: =Cálculo!F44/1000 -> 10 | E13: =D13-C13 -> 10 | F13: =Cálculo!D110 -> -182.6229 | G13: =E13*F13/1000 -> -1.826229 | I13: HDG Ind | J13: =Cálculo!D44 -> 481.23641 | K13: =Cálculo!G44 -> 481.23641 | L13: =K13-J13 -> 0 | M13: =D13 -> 10 | N13: =L13*M13/1000 -> 0
B14: AlZn Ind | C14: =Cálculo!C38/1000 -> 0 | D14: =Cálculo!F38/1000 -> 0 | E14: =D14-C14 -> 0 | F14: =Cálculo!D104 -> -663.85931 | G14: =E14*F14/1000 -> 0 | I14: AlZn Ind | J14: =Cálculo!D38 -> 0 | K14: =Cálculo!G38 -> 0 | L14: =K14-J14 -> 0 | M14: =D14 -> 0 | N14: =L14*M14/1000 -> 0 | DF14: =O14/1000 -> 0
B15: Export | C15: =SUM(C5:C14) -> 3269.91 | D15: =SUM(D5:D14) -> 3096.0096 | E15: =SUM(E5:E14) -> -173.90036 | G15: =SUM(G5:G14) -> -17.954758 | H15: =G15-Box!G14 -> -1.826229 | I15: Export | N15: =SUM(N5:N14) -> 234.40936
B17: Vol (kt) | C17: =C4 -> FY26'B | D17: =D4 -> FY26'F7 | E17: Var | F17: =F4 -> CM FY26'B | G17: MUSD | I17: NRP $/t | J17: =J4 -> FY26'B | K17: =K4 -> FY26'F7 | L17: Var | M17: =M4 -> Vol FY26'F7 | N17: MUSD
B18: Slab | C18: =Cálculo!C20/1000 -> 31 | D18: =Cálculo!F20/1000 -> 32.42416 | E18: =D18-C18 -> 1.42416 | F18: =Cálculo!D86 -> 0.72748999 | G18: =E18*F18/1000 -> 0.0010360621 | I18: Slab | J18: =Cálculo!D20*Cálculo!$E$152 -> 2435.9483 | K18: =Cálculo!G20*Cálculo!$H$152 -> 2403.9567 | L18: =K18-J18 -> -31.991604 | M18: =D18 -> 32.42416 | N18: =L18*M18/1000/$N$38 -> -0.19209276 | O18: =Cálculo!M20 -> -192.09276 | DF18: =O18/1000 -> -0.19209276 | DG18: =N18-DF18 -> 0
B19: Plates | C19: =Cálculo!C21/1000 -> 18 | D19: =Cálculo!F21/1000 -> 16.52916 | E19: =D19-C19 -> -1.47084 | F19: =Cálculo!D87 -> 269.02612 | G19: =E19*F19/1000 -> -0.39569438 | I19: Plates | J19: =Cálculo!D21*Cálculo!$E$152 -> 3701.1609 | K19: =Cálculo!G21*Cálculo!$H$152 -> 3627.0888 | L19: =K19-J19 -> -74.072135 | M19: =D19 -> 16.52916 | N19: =L19*M19/1000/$N$38 -> -0.22673151 | O19: =+Cálculo!M21 -> -226.73151 | DF19: =O19/1000 -> -0.22673151 | DG19: =N19-DF19 -> 0
B20: HRC Auto | C20: =Cálculo!C23/1000 -> 85.81796 | D20: =Cálculo!F23/1000 -> 100.23684 | E20: =D20-C20 -> 14.41888 | F20: =Cálculo!D89 -> 244.22864 | G20: =E20*F20/1000 -> 3.5215036 | I20: HRC Auto | J20: =Cálculo!D23*Cálculo!$E$152 -> 3679.7808 | K20: =Cálculo!G23*Cálculo!$H$152 -> 3757.0515 | L20: =K20-J20 -> 77.270714 | M20: =D20 -> 100.23684 | N20: =L20*M20/1000/$N$38 -> 1.4343282 | O20: =Cálculo!M23 -> 1434.3282 | DF20: =O20/1000 -> 1.4343282 | DG20: =N20-DF20 -> 0
B21: HRC Industry | C21: =Cálculo!C24/1000+Cálculo!C25/1000 -> 1866.0551 | D21: =Cálculo!F24/1000+Cálculo!F25/1000 -> 1888.1302 | E21: =D21-C21 -> 22.07504 | F21: =((Cálculo!E24+Cálculo!E25)/(Cálculo!C24+Cálculo!C25))*1000-((Cálculo!E57+Cálculo!E58)/(Cálculo!C57+Cálculo!C58))*1000 -> 225.39184 | G21: =Box!G20+Box!G21 -> 5.2086109 | I21: HRC Industry | J21: =Cálculo!S24*Cálculo!$E$152 -> 3677.001 | K21: =Cálculo!S25*Cálculo!$H$152 -> 3721.2399 | L21: =K21-J21 -> 44.238826 | M21: =D21 -> 1888.1302 | N21: =Box!N20+Box!N21 -> 14.120804 | DF21: =O21/1000 -> 0 | DG21: =N21-DF21 -> 14.120804
B22: P&O Auto | C22: =Cálculo!C26/1000 -> 102.99919 | D22: =Cálculo!F26/1000 -> 90.523858 | E22: =D22-C22 -> -12.475332 | F22: =Cálculo!D92 -> 341.99386 | G22: =E22*F22/1000 -> -4.266487 | I22: P&O Auto | J22: =Cálculo!D26*Cálculo!$E$152 -> 4639.713 | K22: =Cálculo!G26*Cálculo!$H$152 -> 4733.5026 | L22: =K22-J22 -> 93.789581 | M22: =D22 -> 90.523858 | N22: =L22*M22/1000/$N$38 -> 1.5722583 | DF22: =O22/1000 -> 0 | DG22: =N22-DF22 -> 1.5722583
B23: P&O Ind | C23: =Cálculo!C27/1000 -> 0 | D23: =Cálculo!F27/1000 -> 45.424208 | E23: =D23-C23 -> 45.424208 | F23: =Cálculo!D93 -> 269.38858 | G23: =E23*F23/1000 -> 12.236763 | I23: P&O Ind | J23: =Cálculo!D27*Cálculo!$E$152 -> 3905.6445 | K23: =Cálculo!G27*Cálculo!$H$152 -> 3743.7877 | L23: =K23-J23 -> -161.85682 | M23: =D23 -> 45.424208 | N23: =L23*M23/1000/$N$38 -> -1.3615219 | DF23: =O23/1000 -> 0 | DG23: =N23-DF23 -> -1.3615219
