Workbook

Sheet Cálculo
C2: FY
B3: ="EBITDA "&D15 -> EBITDA FY26'B | C3: =[1]DRE!$O$30/1000 -> 632.04404 | E3: Cálculo | F3: Manual | M3: Atualizar
B4: Forex | C4: =SUM(E4:F4) -> 70.572859 | D4: 26.209989 | E4: =J153/1000 -> 70.572859 | F4: =SUMIF($J$155:$J$181,B4,$I$155:$I$181)/1000 -> 0
B5: Price | C5: =SUM(E5:F5) -> 286.54894 | D5: 17.600765 | E5: =M48/1000 -> 286.54894 | F5: =SUMIF($J$155:$J$181,B5,$I$155:$I$181)/1000 -> 0 | J5: Sales | K5: Var Vol (kt) | L5: Vol/Mix impact | M5: Price impact | P5: Price impact | Q5: Forex
B6: Volume | C6: =SUM(E6:F6) -> -23.126221 | D6: 4.2158522 | E6: =L114/1000 -> -23.126221 | F6: =SUMIF($J$155:$J$181,B6,$I$155:$I$181)/1000 -> 0 | J6: External | K6: =SUM(J83,J84,J88,J94,J95,J99,J100,J104) -> 364878.98 | L6: =SUM(K83,K84,K88,K94,K95,K99,K100,K104) -> 4125.244 | M6: =SUM(M17,M18,M22,M28,M29,M33,M34,M38,M44) -> 175788.85 | P6: =SUM(P17,P18,P22,P28,P29,P33,P34,P38,P44) -> 177667.05 | Q6: =SUM(Q17,Q18,Q22,Q29,Q34,Q38,Q44) -> 0
B7: Mix | C7: =SUM(E7:F7) -> 16.44584 | D7: 1.1809201 | E7: =I114/1000+I166/1000 -> 16.44584 | F7: =SUMIF($J$155:$J$181,B7,$I$155:$I$181)/1000 -> 0 | J7: Domestic | K7: =SUM(J86:J87,J89:J93,J96:J98,J101:J103,J105:J113) -> 58125.113 | L7: =SUM(K86:K87,K89:K93,K96:K98,K101:K103,K105:K109,K111,K110,K112,K113) -> 9448.1482 | M7: =SUM(M20:M21,M23:M27,M30:M32,M35:M37,M39:M47) -> 52139.579 | P7: =SUM(P20:P21,P23:P27,P30:P32,P35:P37,P39:P43,P45,P46,P47) -> 193662.29 | Q7: =SUM(Q20:Q21,Q23:Q27,Q30:Q32,Q35:Q37,Q39:Q47,Q28,Q33) -> 143400.91
B8: Fixed cost | C8: =SUM(E8:F8) -> -34.290559 | D8: 0 | E8: =J126/1000 -> -34.290559 | F8: =SUMIF($J$155:$J$181,B8,$I$155:$I$181)/1000 -> 0 | J8: Total | K8: =SUM(K6:K7) -> 423004.09 | L8: =SUM(L6:L7) -> 13573.392 | M8: =SUM(M6:M7) -> 227928.43 | P8: =SUM(P6:P7) -> 371329.34 | Q8: =SUM(Q6:Q7) -> 143400.91
B9: Input price | C9: =SUM(E9:F9) -> -177.47195 | D9: -60.287404 | E9: =J145/1000 -> -177.47195 | F9: =SUMIF($J$155:$J$181,B9,$I$155:$I$181)/1000 -> 0 | P9: =P8-P48 -> -58620.514
B10: Usage | C10: =SUM(E10:F10) -> -12.829343 | D10: -3.3109603 | E10: =J148/1000 -> -12.829343 | F10: =SUMIF($J$155:$J$181,B10,$I$155:$I$181)/1000 -> 0 | J10: Industry | K10: =SUM(J86:J87,J90,J93,J97,J102,J105,J108,J91,J98,J103,J106,J110,J111,J112,J113) -> 45691.088 | L10: =SUM(K86:K87,K90,K93,K97,K102,K105,K108,K91,K98,K103,K106,K111,K110,K112) -> 4371.2704 | M10: =SUM(M20:M21,M24,M27,M31,M36,M39,M42,M25,M32,M37,M40)+M47+M46+M45 -> 40156.697 | P10: =SUM(P20:P21,P24,P27,P31,P36,P39,P42,P25,P32,P37,P40,P45) -> 144239.63 | Q10: =SUM(Q20:Q21,Q24,Q27,Q31,Q36,Q39,Q42:Q47,Q25,Q32,Q37,Q40)-Q43 -> 104082.93
B11: Others | C11: =SUM(E11:F11) -> -5.7640204 | D11: -2.376185 | F11: =SUMIF($J$155:$J$181,B11,$I$155:$I$181)/1000 -> -5.7640204 | J11: Auto | K11: =SUM(J89,J92,J96,J101,J107,J109) -> 12434.025 | L11: =SUM(K89,K92,K96,K101,K107,K109) -> 5076.8778 | M11: =SUM(M23,M26,M30,M35,M41,M43) -> 11982.881 | P11: =SUM(P23,P26,P30,P35,P41,P43) -> 49422.664 | Q11: =SUM(Q23,Q26,Q30,Q35,Q41,Q43,Q28,Q33) -> 39317.984
B12: Stock variation | C12: =C13-SUM(C3:C11) -> -4.4371962 | D12: -25.205747 | F12: =SUMIF($J$155:$J$181,B12,$I$155:$I$181)/1000 -> -3.8604225 | J12: Check | K12: =K7-K10-K11 -> 0 | L12: =L7-L10-L11 -> 0 | M12: =M7-M10-M11 -> 0 | P12: =P7-P10-P11 -> 0 | Q12: =Q7-Q10-Q11 -> 0
B13: ="EBITDA "&G15 -> EBITDA FY26'F7 | C13: =[2]DRE!$O$30/1000 -> 747.6924 | F13: =F48-F14 -> 0 | J13: Industry & Down KUSD | K13: =SUM(H24:H25,H27,H31:H32,H36:H37,H39:H40,H42) -> 2460560.9
C14: ='[3]Shipments & Prices'!$O$8*1000-C48 -> -0.38 | E14: =E48-'[3]Shipments & Prices'!$O$234 -> 0.1558374 | F14: ='[4]Shipments & Prices'!$O$20*1000 -> 7106558.5 | H14: ='[4]Shipments & Prices'!$O$234-H48 -> 0 | J14: Auto KUSD | K14: =SUM(H23,H26,H30,H35,H41,H43,H20,H21) -> 930071.95
D15: FY26'B | G15: FY26'F7
B16: Sales | C16: kt | D16: USD/t | E16: kUSD | F16: kt | G16: USD/t | H16: kUSD | I16: Sales Mix | J16: Mix Working | K16: Var Price USD | L16: Var Price BRL | M16: Price impact | O16: Var Price USD | P16: Price impact | Q16: Forex
B17: Slab Calvert | C17: ='[3]Shipments & Prices'!$O$23*1000 -> 961000 | D17: =IF(ISERROR((+E17/C17)*1000),0,(+E17/C17)*1000) -> 521.64672 | E17: ='[3]Shipments & Prices'!$O$237 -> 501302.5 | F17: ='[4]Shipments & Prices'!$O$23*1000 -> 966247.87 | G17: =IF(ISERROR((+H17/F17)*1000),0,(+H17/F17)*1000) -> 611.989 | H17: ='[4]Shipments & Prices'!$O$237 -> 591333.07 | I17: =(F17-J17)*D17/1000 -> 11455.529 | J17: =$F$48*C17/$C$48 -> 944287.55 | K17: =G17-D17 -> 90.342283 | M17: =K17*F17/1000 -> 87293.039 | O17: =G17-D17 -> 90.342283 | P17: =O17*F17/1000 -> 87293.039 | Q17: =P17-M17 -> 0
B18: Slabs Others Intragroup | C18: =[5]TUBARÃO_VEGA!$O$614*1000 -> 400000 | D18: =IF(ISERROR((+E18/C18)*1000),0,(+E18/C18)*1000) -> 444.574 | E18: =[5]TUBARÃO_VEGA!$O$626 -> 177829.6 | F18: ='[4]Shipments & Prices'!$O$614*1000 -> 997327.08 | G18: =IF(ISERROR((+H18/F18)*1000),0,(+H18/F18)*1000) -> 516.61738 | H18: ='[4]Shipments & Prices'!$O$626 -> 515236.51 | I18: =(F18-J18)*D18/1000 -> 268648.67 | J18: =$F$48*C18/$C$48 -> 393043.73 | K18: =G18-D18 -> 72.04338 | M18: =K18*F18/1000 -> 71850.814 | O18: =G18-D18 -> 72.04338 | P18: =O18*F18/1000 -> 71850.814 | Q18: =P18-M18 -> 0
B19: Slabs 3rd Party | C19: =[5]TUBARÃO_VEGA!$O$615*1000 -> 1423164.4 | D19: =IF(ISERROR((+E19/C19)*1000),0,(+E19/C19)*1000) -> 453.281 | E19: =[5]TUBARÃO_VEGA!$O$627 -> 645093.38 | F19: ='[4]Shipments & Prices'!$O$615*1000 -> 874385.04 | G19: =IF(ISERROR((+H19/F19)*1000),0,(+H19/F19)*1000) -> 520.32299 | H19: ='[4]Shipments & Prices'!$O$627 -> 454962.64 | I19: =(F19-J19)*D19/1000 -> -237532.63 | J19: =$F$48*C19/$C$48 -> 1398414.6 | K19: =G19-D19 -> 67.04199 | M19: =K19*F19/1000 -> 58620.514 | O19: =G19-D19 -> 67.04199 | P19: =O19*F19/1000 -> 58620.514 | Q19: =P19-M19 -> 0
B20: Slab DM | C20: ='[3]Shipments & Prices'!$O$25*1000 -> 31000 | D20: =IF(ISERROR((+E20/C20)*1000),0,(+E20/C20)*1000) -> 451.10154 | E20: ='[3]Shipments & Prices'!$O$239 -> 13984.148 | F20: ='[4]Shipments & Prices'!$O$25*1000 -> 32424.16 | G20: =IF(ISERROR((+H20/F20)*1000),0,(+H20/F20)*1000) -> 464.42371 | H20: ='[4]Shipments & Prices'!$O$239 -> 15058.549 | I20: =(F20-J20)*D20/1000 -> 885.6347 | J20: =$F$48*C20/$C$48 -> 30460.889 | L20: =(G20*$H$152)-(D20*$E$152) -> -31.991604 | M20: =L20*F20/1000/$E$152 -> -192.09276 | O20: =G20-D20 -> 13.32217 | P20: =O20*F20/1000 -> 431.96016 | Q20: =P20-M20 -> 624.05292
B21: Plates DM | C21: ='[3]Shipments & Prices'!$O$28*1000 -> 18000 | D21: =IF(ISERROR((+E21/C21)*1000),0,(+E21/C21)*1000) -> 685.40017 | E21: ='[3]Shipments & Prices'!$O$242 -> 12337.203 | F21: ='[4]Shipments & Prices'!$O$28*1000 -> 16529.16 | G21: =IF(ISERROR((+H21/F21)*1000),0,(+H21/F21)*1000) -> 700.72228 | H21: ='[4]Shipments & Prices'!$O$242 -> 11582.351 | I21: =(F21-J21)*D21/1000 -> -793.56156 | J21: =$F$48*C21/$C$48 -> 17686.968 | L21: =(G21*$H$152)-(D21*$E$152) -> -74.072135 | M21: =L21*F21/1000/$E$152 -> -226.73151 | O21: =G21-D21 -> 15.32211 | P21: =O21*F21/1000 -> 253.26161 | Q21: =P21-M21 -> 479.99312
B22: HRC Export | C22: ='[3]Shipments & Prices'!$O$30*1000 -> 433467 | D22: =IF(ISERROR((+E22/C22)*1000),0,(+E22/C22)*1000) -> 482.26451 | E22: ='[3]Shipments & Prices'!$O$244 -> 209045.75 | F22: ='[4]Shipments & Prices'!$O$30*1000 -> 197566.82 | G22: =IF(ISERROR((+H22/F22)*1000),0,(+H22/F22)*1000) -> 557.07307 | H22: ='[4]Shipments & Prices'!$O$244 -> 110059.16 | I22: =(F22-J22)*D22/1000 -> -110130.84 | J22: =$F$48*C22/$C$48 -> 425928.71 | K22: =G22-D22 -> 74.80856 | M22: =K22*F22/1000 -> 14779.689 | O22: =G22-D22 -> 74.80856 | P22: =O22*F22/1000 -> 14779.689 | Q22: =P22-M22 -> 0
B23: HRC DM Auto | C23: ='[3]Shipments & Prices'!$O$34*1000 -> 85817.96 | D23: =IF(ISERROR((+E23/C23)*1000),0,(+E23/C23)*1000) -> 681.44089 | E23: ='[3]Shipments & Prices'!$O$248 -> 58479.867 | F23: ='[4]Shipments & Prices'!$O$34*1000 -> 100236.84 | G23: =IF(ISERROR((+H23/F23)*1000),0,(+H23/F23)*1000) -> 725.82997 | H23: ='[4]Shipments & Prices'!$O$248 -> 72754.902 | I23: =(F23-J23)*D23/1000 -> 10842.62 | J23: =$F$48*C23/$C$48 -> 84325.527 | L23: =(G23*$H$152)-(D23*$E$152) -> 77.270714 | M23: =L23*F23/1000/$E$152 -> 1434.3282 | O23: =G23-D23 -> 44.38907 | P23: =O23*F23/1000 -> 4449.4202 | Q23: =P23-M23 -> 3015.092
B24: HRC DM Industry | C24: =('[3]Shipments & Prices'!$O$35)*1000 -> 1438681.3 | D24: =IF(ISERROR((+E24/C24)*1000),0,(+E24/C24)*1000) -> 658.77201 | E24: ='[3]Shipments & Prices'!$O$249 -> 947762.99 | F24: =('[4]Shipments & Prices'!$O$35)*1000 -> 1441770.7 | G24: =IF(ISERROR((+H24/F24)*1000),0,(+H24/F24)*1000) -> 693.84696 | H24: ='[4]Shipments & Prices'!$O$249 -> 1000368.2 | I24: =(F24-J24)*D24/1000 -> 18517.47 | J24: =$F$48*C24/$C$48 -> 1413661.7 | L24: =(G24*$H$152)-(D24*$E$152) -> 34.131787 | M24: =L24*F24/1000/$E$152 -> 9113.0022 | O24: =G24-D24 -> 35.074948 | P24: =O24*F24/1000 -> 50570.033 | Q24: =P24-M24 -> 41457.031
B25: HRC DM Downstream | C25: =+'[3]Shipments & Prices'!$O$36*1000 -> 427373.81 | D25: =IF(ISERROR((+E25/C25)*1000),0,(+E25/C25)*1000) -> 755.50415 | E25: =+'[3]Shipments & Prices'!$O$250 -> 322882.69 | F25: =+'[4]Shipments & Prices'!$O$36*1000 -> 446359.43 | G25: =IF(ISERROR((+H25/F25)*1000),0,(+H25/F25)*1000) -> 799.87146 | H25: ='[4]Shipments & Prices'!$O$250 -> 357030.17 | I25: =(F25-J25)*D25/1000 -> 19958.87 | J25: =$F$48*C25/$C$48 -> 419941.49 | L25: =(G25*$H$152)-(D25*$E$152) -> 60.583747 | M25: =L25*F25/1000/$E$152 -> 5007.8013 | O25: =G25-D25 -> 44.367302 | P25: =O25*F25/1000 -> 19803.764 | Q25: =P25-M25 -> 14795.962
B26: P&O DM Auto | C26: ='[3]Shipments & Prices'!$O$44*1000 -> 102999.19 | D26: =IF(ISERROR((+E26/C26)*1000),0,(+E26/C26)*1000) -> 859.20611 | E26: ='[3]Shipments & Prices'!$O$258 -> 88497.533 | F26: ='[4]Shipments & Prices'!$O$44*1000 -> 90523.858 | G26: =IF(ISERROR((+H26/F26)*1000),0,(+H26/F26)*1000) -> 914.47188 | H26: ='[4]Shipments & Prices'!$O$258 -> 82781.523 | I26: =(F26-J26)*D26/1000 -> -9179.8489 | J26: =$F$48*C26/$C$48 -> 101207.96 | L26: =(G26*$H$152)-(D26*$E$152) -> 93.789581 | M26: =L26*F26/1000/$E$152 -> 1572.2583 | O26: =G26-D26 -> 55.265775 | P26: =O26*F26/1000 -> 5002.8712 | Q26: =P26-M26 -> 3430.6129
B27: P&O DM Industry | C27: ='[3]Shipments & Prices'!$O$45*1000 -> 0 | D27: =G27 -> 723.2675 | E27: ='[3]Shipments & Prices'!$O$259 -> 0 | F27: ='[4]Shipments & Prices'!$O$45*1000 -> 45424.208 | G27: =IF(ISERROR((+H27/F27)*1000),0,(+H27/F27)*1000) -> 723.2675 | H27: ='[4]Shipments & Prices'!$O$259 -> 32853.853 | I27: =(F27-J27)*D27/1000 -> 32853.853 | J27: =$F$48*C27/$C$48 -> 0 | L27: =(G27*$H$152)-(D27*$E$152) -> -161.85682 | M27: =L27*F27/1000/$E$152 -> -1361.5219 | O27: =G27-D27 -> 0 | P27: =O27*F27/1000 -> 0 | Q27: =P27-M27 -> 1361.5219
B28: CRC EM Auto | C28: ='[3]Shipments & Prices'!$O$48*1000 -> 1220.3924 | D28: =IF(ISERROR((+E28/C28)*1000),0,(+E28/C28)*1000) -> 882.99234 | E28: ='[3]Shipments & Prices'!$O$262 -> 1077.5971 | F28: ='[4]Shipments & Prices'!$O$48*1000 -> 1887.8106 | G28: =IF(ISERROR((+H28/F28)*1000),0,(+H28/F28)*1000) -> 937.18709 | H28: ='[4]Shipments & Prices'!$O$262 -> 1769.2317 | I28: =(F28-J28)*D28/1000 -> 608.0653 | J28: =$F$48*C28/$C$48 -> 1199.1689 | L28: =(G28*$H$152)-(D28*$E$152) -> 82.922743 | M28: =L28*F28/1000/$E$152 -> 28.989339 | O28: =G28-D28 -> 54.194756 | P28: =O28*F28/1000 -> 102.30943 | Q28: =P28-M28 -> 73.320093
B29: CRC EM Industry | C29: ='[3]Shipments & Prices'!$O$49*1000 -> 492.26 | D29: =IF(ISERROR((+E29/C29)*1000),0,(+E29/C29)*1000) -> 323.31493 | E29: ='[3]Shipments & Prices'!$O$263 -> 159.15501 | F29: ='[4]Shipments & Prices'!$O$49*1000 -> 4847.375 | G29: =IF(ISERROR((+H29/F29)*1000),0,(+H29/F29)*1000) -> 603.52341 | H29: ='[4]Shipments & Prices'!$O$263 -> 2925.5043 | I29: =(F29-J29)*D29/1000 -> 1410.8415 | J29: =$F$48*C29/$C$48 -> 483.69926 | K29: =G29-D29 -> 280.20848 | M29: =K29*F29/1000 -> 1358.2756 | O29: =G29-D29 -> 280.20848 | P29: =O29*F29/1000 -> 1358.2756 | Q29: =P29-M29 -> 0
B30: CRC DM Auto | C30: ='[3]Shipments & Prices'!$O$51*1000 -> 90127.47 | D30: =IF(ISERROR((+E30/C30)*1000),0,(+E30/C30)*1000) -> 922.02223 | E30: ='[3]Shipments & Prices'!$O$265 -> 83099.531 | F30: ='[4]Shipments & Prices'!$O$51*1000 -> 95622.293 | G30: =IF(ISERROR((+H30/F30)*1000),0,(+H30/F30)*1000) -> 982.99579 | H30: ='[4]Shipments & Prices'!$O$265 -> 93996.312 | I30: =(F30-J30)*D30/1000 -> 6511.5067 | J30: =$F$48*C30/$C$48 -> 88560.092 | L30: =(G30*$H$152)-(D30*$E$152) -> 109.27698 | M30: =L30*F30/1000/$E$152 -> 1935.0584 | O30: =G30-D30 -> 60.973563 | P30: =O30*F30/1000 -> 5830.4319 | Q30: =P30-M30 -> 3895.3736
B31: CRC DM Industry | C31: =('[3]Shipments & Prices'!$O$52)*1000 -> 265325.54 | D31: =IF(ISERROR((+E31/C31)*1000),0,(+E31/C31)*1000) -> 788.21579 | E31: ='[3]Shipments & Prices'!$O$266 -> 209133.78 | F31: =('[4]Shipments & Prices'!$O$52)*1000 -> 286122.32 | G31: =IF(ISERROR((+H31/F31)*1000),0,(+H31/F31)*1000) -> 844.90554 | H31: ='[4]Shipments & Prices'!$O$266 -> 241746.33 | I31: =(F31-J31)*D31/1000 -> 20029.329 | J31: =$F$48*C31/$C$48 -> 260711.35 | L31: =(G31*$H$152)-(D31*$E$152) -> 117.04702 | M31: =L31*F31/1000/$E$152 -> 6201.8085 | O31: =G31-D31 -> 56.689756 | P31: =O31*F31/1000 -> 16220.205 | Q31: =P31-M31 -> 10018.396
B32: CRC DM Downstream | C32: =+'[3]Shipments & Prices'!$O$53*1000 -> 110301.97 | D32: =IF(ISERROR((+E32/C32)*1000),0,(+E32/C32)*1000) -> 833.50042 | E32: =+'[3]Shipments & Prices'!$O$267 -> 91936.738 | F32: =+'[4]Shipments & Prices'!$O$53*1000 -> 117390.91 | G32: =IF(ISERROR((+H32/F32)*1000),0,(+H32/F32)*1000) -> 892.1814 | H32: =+'[4]Shipments & Prices'!$O$267 -> 104733.99 | I32: =(F32-J32)*D32/1000 -> 7507.4783 | J32: =$F$48*C32/$C$48 -> 108383.74 | L32: =(G32*$H$152)-(D32*$E$152) -> 117.21996 | M32: =L32*F32/1000/$E$152 -> 2548.2515 | O32: =G32-D32 -> 58.680977 | P32: =O32*F32/1000 -> 6888.6133 | Q32: =P32-M32 -> 4340.3619
B33: HDG EM Auto | C33: ='[3]Shipments & Prices'!$O$61*1000 -> 49551.853 | D33: =IF(ISERROR((+E33/C33)*1000),0,(+E33/C33)*1000) -> 1018.0181 | E33: ='[3]Shipments & Prices'!$O$275 -> 50444.681 | F33: ='[4]Shipments & Prices'!$O$61*1000 -> 41148.524 | G33: =IF(ISERROR((+H33/F33)*1000),0,(+H33/F33)*1000) -> 1058.4157 | H33: ='[4]Shipments & Prices'!$O$275 -> 43552.244 | I33: =(F33-J33)*D33/1000 -> -7677.4736 | J33: =$F$48*C33/$C$48 -> 48690.112 | L33: =(G33*$H$152)-(D33*$E$152) -> -18.710747 | M33: =L33*F33/1000/$E$152 -> -142.57771 | O33: =G33-D33 -> 40.397668 | P33: =O33*F33/1000 -> 1662.3044 | Q33: =P33-M33 -> 1804.8821
B34: HDG EM Industry | C34: ='[3]Shipments & Prices'!$O$62*1000 -> 1014.12 | D34: =IF(ISERROR((+E34/C34)*1000),0,(+E34/C34)*1000) -> 323.31493 | E34: ='[3]Shipments & Prices'!$O$276 -> 327.88014 | F34: ='[4]Shipments & Prices'!$O$62*1000 -> 2599.121 | G34: =IF(ISERROR((+H34/F34)*1000),0,(+H34/F34)*1000) -> 562.09665 | H34: ='[4]Shipments & Prices'!$O$276 -> 1460.9572 | I34: =(F34-J34)*D34/1000 -> 518.15655 | J34: =$F$48*C34/$C$48 -> 996.48376 | K34: =G34-D34 -> 238.78171 | M34: =K34*F34/1000 -> 620.62257 | O34: =G34-D34 -> 238.78171 | P34: =O34*F34/1000 -> 620.62257 | Q34: =P34-M34 -> 0
B35: HDG DM Auto | C35: ='[3]Shipments & Prices'!$O$64*1000 -> 463694.03 | D35: =IF(ISERROR((+E35/C35)*1000),0,(+E35/C35)*1000) -> 1045.0986 | E35: ='[3]Shipments & Prices'!$O$278 -> 484605.99 | F35: ='[4]Shipments & Prices'!$O$64*1000 -> 463787.29 | G35: =IF(ISERROR((+H35/F35)*1000),0,(+H35/F35)*1000) -> 1098.849 | H35: ='[4]Shipments & Prices'!$O$278 -> 509632.21 | I35: =(F35-J35)*D35/1000 -> 8525.0978 | J35: =$F$48*C35/$C$48 -> 455630.07 | L35: =(G35*$H$152)-(D35*$E$152) -> 44.345684 | M35: =L35*F35/1000/$E$152 -> 3808.6971 | O35: =G35-D35 -> 53.750413 | P35: =O35*F35/1000 -> 24928.758 | Q35: =P35-M35 -> 21120.061
B36: HDG DM Industry | C36: =('[3]Shipments & Prices'!$O$65)*1000 -> 416584.71 | D36: =IF(ISERROR((+E36/C36)*1000),0,(+E36/C36)*1000) -> 848.78295 | E36: ='[3]Shipments & Prices'!$O$279 -> 353590 | F36: =('[4]Shipments & Prices'!$O$65)*1000 -> 438619.17 | G36: =IF(ISERROR((+H36/F36)*1000),0,(+H36/F36)*1000) -> 912.55186 | H36: ='[4]Shipments & Prices'!$O$279 -> 400262.74 | I36: =(F36-J36)*D36/1000 -> 24851.647 | J36: =$F$48*C36/$C$48 -> 409340.02 | L36: =(G36*$H$152)-(D36*$E$152) -> 140.13614 | M36: =L36*F36/1000/$E$152 -> 11382.666 | O36: =G36-D36 -> 63.768902 | P36: =O36*F36/1000 -> 27970.263 | Q36: =P36-M36 -> 16587.597
B37: HDG DM Downstream | C37: =+'[3]Shipments & Prices'!$O$66*1000 -> 83539.33 | D37: =IF(ISERROR((+E37/C37)*1000),0,(+E37/C37)*1000) -> 880.30207 | E37: =+'[3]Shipments & Prices'!$O$280 -> 73539.846 | F37: =+'[4]Shipments & Prices'!$O$66*1000 -> 76159.621 | G37: =IF(ISERROR((+H37/F37)*1000),0,(+H37/F37)*1000) -> 950.63961 | H37: =+'[4]Shipments & Prices'!$O$280 -> 72400.352 | I37: =(F37-J37)*D37/1000 -> -5217.4647 | J37: =$F$48*C37/$C$48 -> 82086.524 | L37: =(G37*$H$152)-(D37*$E$152) -> 167.08325 | M37: =L37*F37/1000/$E$152 -> 2356.481 | O37: =G37-D37 -> 70.337531 | P37: =O37*F37/1000 -> 5356.8797 | Q37: =P37-M37 -> 3000.3988
B38: AlZn Export | C38: ='[3]Shipments & Prices'!$O$74*1000 -> 0 | D38: =IF(ISERROR((+E38/C38)*1000),0,(+E38/C38)*1000) -> 0 | E38: ='[3]Shipments & Prices'!$O$288 -> 0 | F38: ='[4]Shipments & Prices'!$O$74*1000 -> 0 | G38: =IF(ISERROR((+H38/F38)*1000),0,(+H38/F38)*1000) -> 0 | H38: ='[4]Shipments & Prices'!$O$288 -> 0 | I38: =(F38-J38)*D38/1000 -> 0 | J38: =$F$48*C38/$C$48 -> 0 | K38: =G38-D38 -> 0 | M38: =K38*F38/1000 -> 0 | O38: =G38-D38 -> 0 | P38: =O38*F38/1000 -> 0 | Q38: =P38-M38 -> 0
B39: AlZn DM Industry | C39: =('[3]Shipments & Prices'!$O$79)*1000 -> 181457.09 | D39: =IF(ISERROR((+E39/C39)*1000),0,(+E39/C39)*1000) -> 973.02161 | E39: ='[3]Shipments & Prices'!$O$293 -> 176561.67 | F39: =('[4]Shipments & Prices'!$O$79)*1000 -> 136271.79 | G39: =IF(ISERROR((+H39/F39)*1000),0,(+H39/F39)*1000) -> 1027.641 | H39: ='[4]Shipments & Prices'!$O$293 -> 140038.48 | I39: =(F39-J39)*D39/1000 -> -40895.746 | J39: =$F$48*C39/$C$48 -> 178301.43 | L39: =(G39*$H$152)-(D39*$E$152) -> 64.973401 | M39: =L39*F39/1000/$E$152 -> 1639.6373 | O39: =G39-D39 -> 54.619373 | P39: =O39*F39/1000 -> 7443.0797 | Q39: =P39-M39 -> 5803.4424
B40: ALZn DM Downstream | C40: =+'[3]Shipments & Prices'!$O$80*1000 -> 106335.88 | D40: =IF(ISERROR((+E40/C40)*1000),0,(+E40/C40)*1000) -> 1088.1106 | E40: =+'[3]Shipments & Prices'!$O$294 -> 115705.2 | F40: =+'[4]Shipments & Prices'!$O$80*1000 -> 88523.367 | G40: =IF(ISERROR((+H40/F40)*1000),0,(+H40/F40)*1000) -> 1184.3833 | H40: =+'[4]Shipments & Prices'!$O$294 -> 104845.6 | I40: =(F40-J40)*D40/1000 -> -17369.792 | J40: =$F$48*C40/$C$48 -> 104486.63 | L40: =(G40*$H$152)-(D40*$E$152) -> 254.82436 | M40: =L40*F40/1000/$E$152 -> 4177.3908 | O40: =G40-D40 -> 96.272637 | P40: =O40*F40/1000 -> 8522.378 | Q40: =P40-M40 -> 4344.9871
B41: Usibor DM Auto | C41: ='[3]Shipments & Prices'!$O$90*1000 -> 94231.595 | D41: =IF(ISERROR((+E41/C41)*1000),0,(+E41/C41)*1000) -> 1291.3711 | E41: ='[3]Shipments & Prices'!$O$304 -> 121687.96 | F41: ='[4]Shipments & Prices'!$O$90*1000 -> 99323.021 | G41: =IF(ISERROR((+H41/F41)*1000),0,(+H41/F41)*1000) -> 1381.2513 | H41: ='[4]Shipments & Prices'!$O$304 -> 137190.05 | I41: =(F41-J41)*D41/1000 -> 8691.1575 | J41: =$F$48*C41/$C$48 -> 92592.843 | L41: =(G41*$H$152)-(D41*$E$152) -> 176.24927 | M41: =L41*F41/1000/$E$152 -> 3241.7797 | O41: =G41-D41 -> 89.880255 | P41: =O41*F41/1000 -> 8927.1784 | Q41: =P41-M41 -> 5685.3988
...

Sheet Receita
B3: Fontes: | M3: Atualizar
B4: Preço-ex works (Receita SAC)
B5: Cost by stage para o custo variável de forma a calcular a margem de contribuição | J5: Sales | K5: Var Vol (kt) | L5: Vol/Mix impact | M5: Price impact | P5: Price impact | Q5: Forex
B6: Obs: Quando não tem volume no período comparativo, eu coloco o preço igual de forma a não trazer efeito no selling price | J6: External | K6: =SUM(J83,J84,J88,J94,J95,J99,J100,J104) -> 364878.98 | L6: =SUM(K83,K84,K88,K94,K95,K99,K100,K104) -> 4125.244 | M6: =SUM(M17,M18,M22,M28,M29,M33,M34,M38,M44) -> 175788.85 | P6: =SUM(P17,P18,P22,P28,P29,P33,P34,P38,P44) -> 177667.05 | Q6: =SUM(Q17,Q18,Q22,Q29,Q34,Q38,Q44) -> 0
J7: Domestic | K7: =SUM(J86:J87,J89:J93,J96:J98,J101:J103,J105:J113) -> 58125.113 | L7: =SUM(K86:K87,K89:K93,K96:K98,K101:K103,K105:K109,K111,K110,K112,K113) -> 9448.1482 | M7: =SUM(M20:M21,M23:M27,M30:M32,M35:M37,M39:M47) -> 52139.579 | P7: =SUM(P20:P21,P23:P27,P30:P32,P35:P37,P39:P43,P45,P46,P47) -> 193662.29 | Q7: =SUM(Q20:Q21,Q23:Q27,Q30:Q32,Q35:Q37,Q39:Q47,Q28,Q33) -> 143400.91
J8: Total | K8: =SUM(K6:K7) -> 423004.09 | L8: =SUM(L6:L7) -> 13573.392 | M8: =SUM(M6:M7) -> 227928.43 | P8: =SUM(P6:P7) -> 371329.34 | Q8: =SUM(Q6:Q7) -> 143400.91
P9: =P8-P48 -> -58620.514
J10: Industry | K10: =SUM(J86:J87,J90,J93,J97,J102,J105,J108,J91,J98,J103,J106,J110,J111,J112,J113) -> 45691.088 | L10: =SUM(K86:K87,K90,K93,K97,K102,K105,K108,K91,K98,K103,K106,K111,K110,K112) -> 4371.2704 | M10: =SUM(M20:M21,M24,M27,M31,M36,M39,M42,M25,M32,M37,M40)+M47+M46+M45 -> 40156.697 | P10: =SUM(P20:P21,P24,P27,P31,P36,P39,P42,P25,P32,P37,P40,P45) -> 144239.63 | Q10: =SUM(Q20:Q21,Q24,Q27,Q31,Q36,Q39,Q42:Q47,Q25,Q32,Q37,Q40)-Q43 -> 104082.93
J11: Auto | K11: =SUM(J89,J92,J96,J101,J107,J109) -> 12434.025 | L11: =SUM(K89,K92,K96,K101,K107,K109) -> 5076.8778 | M11: =SUM(M23,M26,M30,M35,M41,M43) -> 11982.881 | P11: =SUM(P23,P26,P30,P35,P41,P43) -> 49422.664 | Q11: =SUM(Q23,Q26,Q30,Q35,Q41,Q43,Q28,Q33) -> 39317.984
J12: Check | K12: =K7-K10-K11 -> 0 | L12: =L7-L10-L11 -> 0 | M12: =M7-M10-M11 -> 0 | P12: =P7-P10-P11 -> 0 | Q12: =Q7-Q10-Q11 -> 0
J13: Industry & Down KUSD | K13: =SUM(H24:H25,H27,H31:H32,H36:H37,H39:H40,H42) -> 2460560.9
C14: ='[3]Shipments & Prices'!$O$8*1000-C48 -> -0.38 | E14: =E48-'[3]Shipments & Prices'!$O$234 -> 0.1558374 | F14: ='[4]Shipments & Prices'!$O$20*1000 -> 7106558.5 | H14: ='[4]Shipments & Prices'!$O$234-H48 -> 0 | J14: Auto KUSD | K14: =SUM(H23,H26,H30,H35,H41,H43,H20,H21) -> 930071.95
D15: FY26'B | G15: FY26'F7
B16: Sales | C16: kt | D16: USD/t | E16: kUSD | F16: kt | G16: USD/t | H16: kUSD | I16: Sales Mix | J16: Mix Working | K16: Var Price USD | L16: Var Price BRL | M16: Price impact | O16: Var Price USD | P16: Price impact | Q16: Forex
B17: Slab Calvert | C17: ='[3]Shipments & Prices'!$O$23*1000 -> 961000 | D17: =IF(ISERROR((+E17/C17)*1000),0,(+E17/C17)*1000) -> 521.64672 | E17: ='[3]Shipments & Prices'!$O$237 -> 501302.5 | F17: ='[4]Shipments & Prices'!$O$23*1000 -> 966247.87 | G17: =IF(ISERROR((+H17/F17)*1000),0,(+H17/F17)*1000) -> 611.989 | H17: ='[4]Shipments & Prices'!$O$237 -> 591333.07 | I17: =(F17-J17)*D17/1000 -> 11455.529 | J17: =$F$48*C17/$C$48 -> 944287.55 | K17: =G17-D17 -> 90.342283 | M17: =K17*F17/1000 -> 87293.039 | O17: =G17-D17 -> 90.342283 | P17: =O17*F17/1000 -> 87293.039 | Q17: =P17-M17 -> 0
B18: Slabs Others Intragroup | C18: =[5]TUBARÃO_VEGA!$O$614*1000 -> 400000 | D18: =IF(ISERROR((+E18/C18)*1000),0,(+E18/C18)*1000) -> 444.574 | E18: =[5]TUBARÃO_VEGA!$O$626 -> 177829.6 | F18: ='[4]Shipments & Prices'!$O$614*1000 -> 997327.08 | G18: =IF(ISERROR((+H18/F18)*1000),0,(+H18/F18)*1000) -> 516.61738 | H18: ='[4]Shipments & Prices'!$O$626 -> 515236.51 | I18: =(F18-J18)*D18/1000 -> 268648.67 | J18: =$F$48*C18/$C$48 -> 393043.73 | K18: =G18-D18 -> 72.04338 | M18: =K18*F18/1000 -> 71850.814 | O18: =G18-D18 -> 72.04338 | P18: =O18*F18/1000 -> 71850.814 | Q18: =P18-M18 -> 0
B19: Slabs 3rd Party | C19: =[5]TUBARÃO_VEGA!$O$615*1000 -> 1423164.4 | D19: =IF(ISERROR((+E19/C19)*1000),0,(+E19/C19)*1000) -> 453.281 | E19: =[5]TUBARÃO_VEGA!$O$627 -> 645093.38 | F19: ='[4]Shipments & Prices'!$O$615*1000 -> 874385.04 | G19: =IF(ISERROR((+H19/F19)*1000),0,(+H19/F19)*1000) -> 520.32299 | H19: ='[4]Shipments & Prices'!$O$627 -> 454962.64 | I19: =(F19-J19)*D19/1000 -> -237532.63 | J19: =$F$48*C19/$C$48 -> 1398414.6 | K19: =G19-D19 -> 67.04199 | M19: =K19*F19/1000 -> 58620.514 | O19: =G19-D19 -> 67.04199 | P19: =O19*F19/1000 -> 58620.514 | Q19: =P19-M19 -> 0
B20: Slab DM | C20: ='[3]Shipments & Prices'!$O$25*1000 -> 31000 | D20: =IF(ISERROR((+E20/C20)*1000),0,(+E20/C20)*1000) -> 451.10154 | E20: ='[3]Shipments & Prices'!$O$239 -> 13984.148 | F20: ='[4]Shipments & Prices'!$O$25*1000 -> 32424.16 | G20: =IF(ISERROR((+H20/F20)*1000),0,(+H20/F20)*1000) -> 464.42371 | H20: ='[4]Shipments & Prices'!$O$239 -> 15058.549 | I20: =(F20-J20)*D20/1000 -> 885.6347 | J20: =$F$48*C20/$C$48 -> 30460.889 | L20: =(G20*$H$116)-(D20*$E$116) -> -31.991604 | M20: =L20*F20/1000/$E$116 -> -192.09276 | O20: =G20-D20 -> 13.32217 | P20: =O20*F20/1000 -> 431.96016 | Q20: =P20-M20 -> 624.05292
B21: Plates DM | C21: ='[3]Shipments & Prices'!$O$28*1000 -> 18000 | D21: =IF(ISERROR((+E21/C21)*1000),0,(+E21/C21)*1000) -> 685.40017 | E21: ='[3]Shipments & Prices'!$O$242 -> 12337.203 | F21: ='[4]Shipments & Prices'!$O$28*1000 -> 16529.16 | G21: =IF(ISERROR((+H21/F21)*1000),0,(+H21/F21)*1000) -> 700.72228 | H21: ='[4]Shipments & Prices'!$O$242 -> 11582.351 | I21: =(F21-J21)*D21/1000 -> -793.56156 | J21: =$F$48*C21/$C$48 -> 17686.968 | L21: =(G21*$H$116)-(D21*$E$116) -> -74.072135 | M21: =L21*F21/1000/$E$116 -> -226.73151 | O21: =G21-D21 -> 15.32211 | P21: =O21*F21/1000 -> 253.26161 | Q21: =P21-M21 -> 479.99312
B22: HRC Export | C22: ='[3]Shipments & Prices'!$O$30*1000 -> 433467 | D22: =IF(ISERROR((+E22/C22)*1000),0,(+E22/C22)*1000) -> 482.26451 | E22: ='[3]Shipments & Prices'!$O$244 -> 209045.75 | F22: ='[4]Shipments & Prices'!$O$30*1000 -> 197566.82 | G22: =IF(ISERROR((+H22/F22)*1000),0,(+H22/F22)*1000) -> 557.07307 | H22: ='[4]Shipments & Prices'!$O$244 -> 110059.16 | I22: =(F22-J22)*D22/1000 -> -110130.84 | J22: =$F$48*C22/$C$48 -> 425928.71 | K22: =G22-D22 -> 74.80856 | M22: =K22*F22/1000 -> 14779.689 | O22: =G22-D22 -> 74.80856 | P22: =O22*F22/1000 -> 14779.689 | Q22: =P22-M22 -> 0
B23: HRC DM Auto | C23: ='[3]Shipments & Prices'!$O$34*1000 -> 85817.96 | D23: =IF(ISERROR((+E23/C23)*1000),0,(+E23/C23)*1000) -> 681.44089 | E23: ='[3]Shipments & Prices'!$O$248 -> 58479.867 | F23: ='[4]Shipments & Prices'!$O$34*1000 -> 100236.84 | G23: =IF(ISERROR((+H23/F23)*1000),0,(+H23/F23)*1000) -> 725.82997 | H23: ='[4]Shipments & Prices'!$O$248 -> 72754.902 | I23: =(F23-J23)*D23/1000 -> 10842.62 | J23: =$F$48*C23/$C$48 -> 84325.527 | L23: =(G23*$H$116)-(D23*$E$116) -> 77.270714 | M23: =L23*F23/1000/$E$116 -> 1434.3282 | O23: =G23-D23 -> 44.38907 | P23: =O23*F23/1000 -> 4449.4202 | Q23: =P23-M23 -> 3015.092
B24: HRC DM Industry | C24: =('[3]Shipments & Prices'!$O$35)*1000 -> 1438681.3 | D24: =IF(ISERROR((+E24/C24)*1000),0,(+E24/C24)*1000) -> 658.77201 | E24: ='[3]Shipments & Prices'!$O$249 -> 947762.99 | F24: =('[4]Shipments & Prices'!$O$35)*1000 -> 1441770.7 | G24: =IF(ISERROR((+H24/F24)*1000),0,(+H24/F24)*1000) -> 693.84696 | H24: ='[4]Shipments & Prices'!$O$249 -> 1000368.2 | I24: =(F24-J24)*D24/1000 -> 18517.47 | J24: =$F$48*C24/$C$48 -> 1413661.7 | L24: =(G24*$H$116)-(D24*$E$116) -> 34.131787 | M24: =L24*F24/1000/$E$116 -> 9113.0022 | O24: =G24-D24 -> 35.074948 | P24: =O24*F24/1000 -> 50570.033 | Q24: =P24-M24 -> 41457.031
B25: HRC DM Downstream | C25: =+'[3]Shipments & Prices'!$O$36*1000 -> 427373.81 | D25: =IF(ISERROR((+E25/C25)*1000),0,(+E25/C25)*1000) -> 755.50415 | E25: =+'[3]Shipments & Prices'!$O$250 -> 322882.69 | F25: =+'[4]Shipments & Prices'!$O$36*1000 -> 446359.43 | G25: =IF(ISERROR((+H25/F25)*1000),0,(+H25/F25)*1000) -> 799.87146 | H25: ='[4]Shipments & Prices'!$O$250 -> 357030.17 | I25: =(F25-J25)*D25/1000 -> 19958.87 | J25: =$F$48*C25/$C$48 -> 419941.49 | L25: =(G25*$H$116)-(D25*$E$116) -> 60.583747 | M25: =L25*F25/1000/$E$116 -> 5007.8013 | O25: =G25-D25 -> 44.367302 | P25: =O25*F25/1000 -> 19803.764 | Q25: =P25-M25 -> 14795.962
B26: P&O DM Auto | C26: ='[3]Shipments & Prices'!$O$44*1000 -> 102999.19 | D26: =IF(ISERROR((+E26/C26)*1000),0,(+E26/C26)*1000) -> 859.20611 | E26: ='[3]Shipments & Prices'!$O$258 -> 88497.533 | F26: ='[4]Shipments & Prices'!$O$44*1000 -> 90523.858 | G26: =IF(ISERROR((+H26/F26)*1000),0,(+H26/F26)*1000) -> 914.47188 | H26: ='[4]Shipments & Prices'!$O$258 -> 82781.523 | I26: =(F26-J26)*D26/1000 -> -9179.8489 | J26: =$F$48*C26/$C$48 -> 101207.96 | L26: =(G26*$H$116)-(D26*$E$116) -> 93.789581 | M26: =L26*F26/1000/$E$116 -> 1572.2583 | O26: =G26-D26 -> 55.265775 | P26: =O26*F26/1000 -> 5002.8712 | Q26: =P26-M26 -> 3430.6129
B27: P&O DM Industry | C27: ='[3]Shipments & Prices'!$O$45*1000 -> 0 | D27: =G27 -> 723.2675 | E27: ='[3]Shipments & Prices'!$O$259 -> 0 | F27: ='[4]Shipments & Prices'!$O$45*1000 -> 45424.208 | G27: =IF(ISERROR((+H27/F27)*1000),0,(+H27/F27)*1000) -> 723.2675 | H27: ='[4]Shipments & Prices'!$O$259 -> 32853.853 | I27: =(F27-J27)*D27/1000 -> 32853.853 | J27: =$F$48*C27/$C$48 -> 0 | L27: =(G27*$H$116)-(D27*$E$116) -> -161.85682 | M27: =L27*F27/1000/$E$116 -> -1361.5219 | O27: =G27-D27 -> 0 | P27: =O27*F27/1000 -> 0 | Q27: =P27-M27 -> 1361.5219
B28: CRC EM Auto | C28: ='[3]Shipments & Prices'!$O$48*1000 -> 1220.3924 | D28: =IF(ISERROR((+E28/C28)*1000),0,(+E28/C28)*1000) -> 882.99234 | E28: ='[3]Shipments & Prices'!$O$262 -> 1077.5971 | F28: ='[4]Shipments & Prices'!$O$48*1000 -> 1887.8106 | G28: =IF(ISERROR((+H28/F28)*1000),0,(+H28/F28)*1000) -> 937.18709 | H28: ='[4]Shipments & Prices'!$O$262 -> 1769.2317 | I28: =(F28-J28)*D28/1000 -> 608.0653 | J28: =$F$48*C28/$C$48 -> 1199.1689 | L28: =(G28*$H$116)-(D28*$E$116) -> 82.922743 | M28: =L28*F28/1000/$E$116 -> 28.989339 | O28: =G28-D28 -> 54.194756 | P28: =O28*F28/1000 -> 102.30943 | Q28: =P28-M28 -> 73.320093
B29: CRC EM Industry | C29: ='[3]Shipments & Prices'!$O$49*1000 -> 492.26 | D29: =IF(ISERROR((+E29/C29)*1000),0,(+E29/C29)*1000) -> 323.31493 | E29: ='[3]Shipments & Prices'!$O$263 -> 159.15501 | F29: ='[4]Shipments & Prices'!$O$49*1000 -> 4847.375 | G29: =IF(ISERROR((+H29/F29)*1000),0,(+H29/F29)*1000) -> 603.52341 | H29: ='[4]Shipments & Prices'!$O$263 -> 2925.5043 | I29: =(F29-J29)*D29/1000 -> 1410.8415 | J29: =$F$48*C29/$C$48 -> 483.69926 | K29: =G29-D29 -> 280.20848 | M29: =K29*F29/1000 -> 1358.2756 | O29: =G29-D29 -> 280.20848 | P29: =O29*F29/1000 -> 1358.2756 | Q29: =P29-M29 -> 0
B30: CRC DM Auto | C30: ='[3]Shipments & Prices'!$O$51*1000 -> 90127.47 | D30: =IF(ISERROR((+E30/C30)*1000),0,(+E30/C30)*1000) -> 922.02223 | E30: ='[3]Shipments & Prices'!$O$265 -> 83099.531 | F30: ='[4]Shipments & Prices'!$O$51*1000 -> 95622.293 | G30: =IF(ISERROR((+H30/F30)*1000),0,(+H30/F30)*1000) -> 982.99579 | H30: ='[4]Shipments & Prices'!$O$265 -> 93996.312 | I30: =(F30-J30)*D30/1000 -> 6511.5067 | J30: =$F$48*C30/$C$48 -> 88560.092 | L30: =(G30*$H$116)-(D30*$E$116) -> 109.27698 | M30: =L30*F30/1000/$E$116 -> 1935.0584 | O30: =G30-D30 -> 60.973563 | P30: =O30*F30/1000 -> 5830.4319 | Q30: =P30-M30 -> 3895.3736
B31: CRC DM Industry | C31: =('[3]Shipments & Prices'!$O$52)*1000 -> 265325.54 | D31: =IF(ISERROR((+E31/C31)*1000),0,(+E31/C31)*1000) -> 788.21579 | E31: ='[3]Shipments & Prices'!$O$266 -> 209133.78 | F31: =('[4]Shipments & Prices'!$O$52)*1000 -> 286122.32 | G31: =IF(ISERROR((+H31/F31)*1000),0,(+H31/F31)*1000) -> 844.90554 | H31: ='[4]Shipments & Prices'!$O$266 -> 241746.33 | I31: =(F31-J31)*D31/1000 -> 20029.329 | J31: =$F$48*C31/$C$48 -> 260711.35 | L31: =(G31*$H$116)-(D31*$E$116) -> 117.04702 | M31: =L31*F31/1000/$E$116 -> 6201.8085 | O31: =G31-D31 -> 56.689756 | P31: =O31*F31/1000 -> 16220.205 | Q31: =P31-M31 -> 10018.396
B32: CRC DM Downstream | C32: =+'[3]Shipments & Prices'!$O$53*1000 -> 110301.97 | D32: =IF(ISERROR((+E32/C32)*1000),0,(+E32/C32)*1000) -> 833.50042 | E32: =+'[3]Shipments & Prices'!$O$267 -> 91936.738 | F32: =+'[4]Shipments & Prices'!$O$53*1000 -> 117390.91 | G32: =IF(ISERROR((+H32/F32)*1000),0,(+H32/F32)*1000) -> 892.1814 | H32: =+'[4]Shipments & Prices'!$O$267 -> 104733.99 | I32: =(F32-J32)*D32/1000 -> 7507.4783 | J32: =$F$48*C32/$C$48 -> 108383.74 | L32: =(G32*$H$116)-(D32*$E$116) -> 117.21996 | M32: =L32*F32/1000/$E$116 -> 2548.2515 | O32: =G32-D32 -> 58.680977 | P32: =O32*F32/1000 -> 6888.6133 | Q32: =P32-M32 -> 4340.3619
B33: HDG EM Auto | C33: ='[3]Shipments & Prices'!$O$61*1000 -> 49551.853 | D33: =IF(ISERROR((+E33/C33)*1000),0,(+E33/C33)*1000) -> 1018.0181 | E33: ='[3]Shipments & Prices'!$O$275 -> 50444.681 | F33: ='[4]Shipments & Prices'!$O$61*1000 -> 41148.524 | G33: =IF(ISERROR((+H33/F33)*1000),0,(+H33/F33)*1000) -> 1058.4157 | H33: ='[4]Shipments & Prices'!$O$275 -> 43552.244 | I33: =(F33-J33)*D33/1000 -> -7677.4736 | J33: =$F$48*C33/$C$48 -> 48690.112 | L33: =(G33*$H$116)-(D33*$E$116) -> -18.710747 | M33: =L33*F33/1000/$E$116 -> -142.57771 | O33: =G33-D33 -> 40.397668 | P33: =O33*F33/1000 -> 1662.3044 | Q33: =P33-M33 -> 1804.8821
B34: HDG EM Industry | C34: ='[3]Shipments & Prices'!$O$62*1000 -> 1014.12 | D34: =IF(ISERROR((+E34/C34)*1000),0,(+E34/C34)*1000) -> 323.31493 | E34: ='[3]Shipments & Prices'!$O$276 -> 327.88014 | F34: ='[4]Shipments & Prices'!$O$62*1000 -> 2599.121 | G34: =IF(ISERROR((+H34/F34)*1000),0,(+H34/F34)*1000) -> 562.09665 | H34: ='[4]Shipments & Prices'!$O$276 -> 1460.9572 | I34: =(F34-J34)*D34/1000 -> 518.15655 | J34: =$F$48*C34/$C$48 -> 996.48376 | K34: =G34-D34 -> 238.78171 | M34: =K34*F34/1000 -> 620.62257 | O34: =G34-D34 -> 238.78171 | P34: =O34*F34/1000 -> 620.62257 | Q34: =P34-M34 -> 0
B35: HDG DM Auto | C35: ='[3]Shipments & Prices'!$O$64*1000 -> 463694.03 | D35: =IF(ISERROR((+E35/C35)*1000),0,(+E35/C35)*1000) -> 1045.0986 | E35: ='[3]Shipments & Prices'!$O$278 -> 484605.99 | F35: ='[4]Shipments & Prices'!$O$64*1000 -> 463787.29 | G35: =IF(ISERROR((+H35/F35)*1000),0,(+H35/F35)*1000) -> 1098.849 | H35: ='[4]Shipments & Prices'!$O$278 -> 509632.21 | I35: =(F35-J35)*D35/1000 -> 8525.0978 | J35: =$F$48*C35/$C$48 -> 455630.07 | L35: =(G35*$H$116)-(D35*$E$116) -> 44.345684 | M35: =L35*F35/1000/$E$116 -> 3808.6971 | O35: =G35-D35 -> 53.750413 | P35: =O35*F35/1000 -> 24928.758 | Q35: =P35-M35 -> 21120.061
B36: HDG DM Industry | C36: =('[3]Shipments & Prices'!$O$65)*1000 -> 416584.71 | D36: =IF(ISERROR((+E36/C36)*1000),0,(+E36/C36)*1000) -> 848.78295 | E36: ='[3]Shipments & Prices'!$O$279 -> 353590 | F36: =('[4]Shipments & Prices'!$O$65)*1000 -> 438619.17 | G36: =IF(ISERROR((+H36/F36)*1000),0,(+H36/F36)*1000) -> 912.55186 | H36: ='[4]Shipments & Prices'!$O$279 -> 400262.74 | I36: =(F36-J36)*D36/1000 -> 24851.647 | J36: =$F$48*C36/$C$48 -> 409340.02 | L36: =(G36*$H$116)-(D36*$E$116) -> 140.13614 | M36: =L36*F36/1000/$E$116 -> 11382.666 | O36: =G36-D36 -> 63.768902 | P36: =O36*F36/1000 -> 27970.263 | Q36: =P36-M36 -> 16587.597
B37: HDG DM Downstream | C37: =+'[3]Shipments & Prices'!$O$66*1000 -> 83539.33 | D37: =IF(ISERROR((+E37/C37)*1000),0,(+E37/C37)*1000) -> 880.30207 | E37: =+'[3]Shipments & Prices'!$O$280 -> 73539.846 | F37: =+'[4]Shipments & Prices'!$O$66*1000 -> 76159.621 | G37: =IF(ISERROR((+H37/F37)*1000),0,(+H37/F37)*1000) -> 950.63961 | H37: =+'[4]Shipments & Prices'!$O$280 -> 72400.352 | I37: =(F37-J37)*D37/1000 -> -5217.4647 | J37: =$F$48*C37/$C$48 -> 82086.524 | L37: =(G37*$H$116)-(D37*$E$116) -> 167.08325 | M37: =L37*F37/1000/$E$116 -> 2356.481 | O37: =G37-D37 -> 70.337531 | P37: =O37*F37/1000 -> 5356.8797 | Q37: =P37-M37 -> 3000.3988
B38: AlZn Export | C38: ='[3]Shipments & Prices'!$O$74*1000 -> 0 | D38: =IF(ISERROR((+E38/C38)*1000),0,(+E38/C38)*1000) -> 0 | E38: ='[3]Shipments & Prices'!$O$288 -> 0 | F38: ='[4]Shipments & Prices'!$O$74*1000 -> 0 | G38: =IF(ISERROR((+H38/F38)*1000),0,(+H38/F38)*1000) -> 0 | H38: ='[4]Shipments & Prices'!$O$288 -> 0 | I38: =(F38-J38)*D38/1000 -> 0 | J38: =$F$48*C38/$C$48 -> 0 | K38: =G38-D38 -> 0 | M38: =K38*F38/1000 -> 0 | O38: =G38-D38 -> 0 | P38: =O38*F38/1000 -> 0 | Q38: =P38-M38 -> 0
B39: AlZn DM Industry | C39: =('[3]Shipments & Prices'!$O$79)*1000 -> 181457.09 | D39: =IF(ISERROR((+E39/C39)*1000),0,(+E39/C39)*1000) -> 973.02161 | E39: ='[3]Shipments & Prices'!$O$293 -> 176561.67 | F39: =('[4]Shipments & Prices'!$O$79)*1000 -> 136271.79 | G39: =IF(ISERROR((+H39/F39)*1000),0,(+H39/F39)*1000) -> 1027.641 | H39: ='[4]Shipments & Prices'!$O$293 -> 140038.48 | I39: =(F39-J39)*D39/1000 -> -40895.746 | J39: =$F$48*C39/$C$48 -> 178301.43 | L39: =(G39*$H$116)-(D39*$E$116) -> 64.973401 | M39: =L39*F39/1000/$E$116 -> 1639.6373 | O39: =G39-D39 -> 54.619373 | P39: =O39*F39/1000 -> 7443.0797 | Q39: =P39-M39 -> 5803.4424
B40: ALZn DM Downstream | C40: =+'[3]Shipments & Prices'!$O$80*1000 -> 106335.88 | D40: =IF(ISERROR((+E40/C40)*1000),0,(+E40/C40)*1000) -> 1088.1106 | E40: =+'[3]Shipments & Prices'!$O$294 -> 115705.2 | F40: =+'[4]Shipments & Prices'!$O$80*1000 -> 88523.367 | G40: =IF(ISERROR((+H40/F40)*1000),0,(+H40/F40)*1000) -> 1184.3833 | H40: =+'[4]Shipments & Prices'!$O$294 -> 104845.6 | I40: =(F40-J40)*D40/1000 -> -17369.792 | J40: =$F$48*C40/$C$48 -> 104486.63 | L40: =(G40*$H$116)-(D40*$E$116) -> 254.82436 | M40: =L40*F40/1000/$E$116 -> 4177.3908 | O40: =G40-D40 -> 96.272637 | P40: =O40*F40/1000 -> 8522.378 | Q40: =P40-M40 -> 4344.9871
B41: Usibor DM Auto | C41: ='[3]Shipments & Prices'!$O$90*1000 -> 94231.595 | D41: =IF(ISERROR((+E41/C41)*1000),0,(+E41/C41)*1000) -> 1291.3711 | E41: ='[3]Shipments & Prices'!$O$304 -> 121687.96 | F41: ='[4]Shipments & Prices'!$O$90*1000 -> 99323.021 | G41: =IF(ISERROR((+H41/F41)*1000),0,(+H41/F41)*1000) -> 1381.2513 | H41: ='[4]Shipments & Prices'!$O$304 -> 137190.05 | I41: =(F41-J41)*D41/1000 -> 8691.1575 | J41: =$F$48*C41/$C$48 -> 92592.843 | L41: =(G41*$H$116)-(D41*$E$116) -> 176.24927 | M41: =L41*F41/1000/$E$116 -> 3241.7797 | O41: =G41-D41 -> 89.880255 | P41: =O41*F41/1000 -> 8927.1784 | Q41: =P41-M41 -> 5685.3988
B42: AlSi DM Industry | C42: ='[3]Shipments & Prices'!$O$91*1000 -> 7737.54 | D42: =IF(ISERROR((+E42/C42)*1000),0,(+E42/C42)*1000) -> 848.71896 | E42: ='[3]Shipments & Prices'!$O$305 -> 6566.9969 | F42: ='[4]Shipments & Prices'!$O$91*1000 -> 7661.225 | G42: =IF(ISERROR((+H42/F42)*1000),0,(+H42/F42)*1000) -> 819.85822 | H42: ='[4]Shipments & Prices'!$O$305 -> 6281.1183 | I42: =(F42-J42)*D42/1000 -> 49.434597 | J42: =$F$48*C42/$C$48 -> 7602.9789 | L42: =(G42*$H$116)-(D42*$E$116) -> -339.32045 | M42: =L42*F42/1000/$E$116 -> -481.40931 | O42: =G42-D42 -> -28.860744 | P42: =O42*F42/1000 -> -221.10865 | Q42: =P42-M42 -> 260.30066
...

Sheet Input price
B2: Fonte:
B3: Breakdown
B4: Buscar a informação no foundation (MCR)
B5: USD
B7: Input price | D7: USD/t | G7: USD/t | I7: Yield MRF | J7: Input price
B8: Coal | D8: =[9]FY_Budget!K11 -> 192.44908 | G8: =[9]FY_Budget!O11 -> 209.83033 | I8: =[9]FY_Budget!N11 -> 0.39731562 | J8: =(D8-G8)*I8*$G$24 -> -48135.71
B9: PCI | D9: =[9]FY_Budget!K12 -> 193.47908 | G9: =[9]FY_Budget!O12 -> 218.48672 | I9: =[9]FY_Budget!N12 -> 0.27102848 | J9: =(D9-G9)*I9*$G$24 -> -47243.088
B10: Others (Antracito) | D10: =[9]FY_Budget!K13 -> 0 | G10: =[9]FY_Budget!O13 -> 0 | I10: =[9]FY_Budget!N13 -> 0 | J10: =(D10-G10)*I10*$G$24 -> 0
B11: Purchased coke | D11: =[9]FY_Budget!K14 -> 312.92945 | G11: =[9]FY_Budget!O14 -> 340.61823 | I11: =[9]FY_Budget!N14 -> 0.014076067 | J11: =(D11-G11)*I11*$G$24 -> -2716.6629
B12: Fines | D12: =[9]FY_Budget!K16 -> 72.724806 | G12: =[9]FY_Budget!O16 -> 75.803894 | I12: =[9]FY_Budget!N16 -> 0.50546148 | J12: =(D12-G12)*I12*$G$24 -> -10848.277
B13: Pellets | D13: =[9]FY_Budget!K17 -> 121.43893 | G13: =[9]FY_Budget!O17 -> 128.95793 | I13: =[9]FY_Budget!N17 -> 0.7869986 | J13: =(D13-G13)*I13*$G$24 -> -41246.241
B14: Lumps | D14: =[9]FY_Budget!K18 -> 82.183924 | G14: =[9]FY_Budget!O18 -> 83.470247 | I14: =[9]FY_Budget!N18 -> 0.2207054 | J14: =(D14-G14)*I14*$G$24 -> -1978.8532
B15: Alloys | J15: ='[10]Bridges IP'!$U$6*1000 -> -12014.339
B16: Zinc | J16: ='[10]Bridges IP'!$U$7*1000 -> -11030
B17: AMS allocation fee | D17: ='[11]FCF & OWCR - BUDGET'!$Z$332*1000 -> 19003.748 | G17: ='[12]FCF & OWCR - BUDGET'!$Z$332*1000 -> 25568.07 | J17: =G17-D17 -> 6564.3217
B18: Natural Gas | J18: ='[10]Bridges IP'!$U$9*1000 -> 206.90204
B19: Fluxes | J19: ='[10]Bridges IP'!$U$8*1000 -> -7030
B20: Energy | J20: ='[10]Bridges IP'!$U$10*1000 -> -2000
B21: Refractories
B22: Var. contractors
B23: Freight rate
B24: Crude Steel production | G24: =[9]FY_Budget!$M$38/1000 -> 6970.2857
B25: Total Input price | J25: =SUM(J8:J24) -> -177471.95
O60: =#REF! -> #REF!
O61: =

Sheet Usage
B2: Fonte;
B3: MCR (foundation)
B4: Abrir em market driven e performance operacional
C6: FY
B7: Usage | J7: Usage
J8: ='[10]Bridges complementares'!$F$17*1000 -> -12829.343
O51: =#REF! -> #REF!
O52: =

Sheet Fixed Cost
B3: Fonte:
B4: MCR (foundation)
B6: Fixed Costs | E6: kUSD | H6: kUSD | I6: FC Forex | J6: Fixed Cost
B7: Labor | E7: =[8]FYB26xFYMRF7!$D$9+[8]FYB26xFYMRF7!$D$35 -> 290502.46 | H7: =[8]FYB26xFYMRF7!$G$9+[8]FYB26xFYMRF7!$G$35 -> 335945.76 | I7: =H7*($H$16/$E$16-1) -> -14075.791 | J7: =E7-H7-I7 -> -31367.507
B8: R&M | E8: =[8]FYB26xFYMRF7!$D$10 -> 162910.38 | H8: =[8]FYB26xFYMRF7!$G$10 -> 173542.34 | I8: =H8*($H$16/$E$16-1) -> -7271.2501 | J8: =E8-H8-I8 -> -3360.7127
B9: R&M USD | E9: =[8]FYB26xFYMRF7!$D$11 -> 455.31969 | H9: =[8]FYB26xFYMRF7!$G$11 -> 476.59813 | J9: =E9-H9-I9 -> -21.278439
B10: SG&A | E10: =[8]FYB26xFYMRF7!$D$12+[8]FYB26xFYMRF7!$D$34 -> 36445.37 | H10: =[8]FYB26xFYMRF7!$G$12+[8]FYB26xFYMRF7!$G$34 -> 39799.933 | I10: =H10*($H$16/$E$16-1) -> -1667.5773 | J10: =E10-H10-I10 -> -1686.9865
B11: SG&A USD | E11: =[8]FYB26xFYMRF7!$D$13 -> 4329.6571 | H11: =[8]FYB26xFYMRF7!$G$13 -> 4366.7997 | J11: =E11-H11-I11 -> -37.142574
B12: SG&A NC | E12: =[8]FYB26xFYMRF7!$D$14 -> 0 | H12: =[8]FYB26xFYMRF7!$G$14 -> 0 | I12: =H12*($H$16/$E$16-1) -> 0 | J12: =E12-H12-I12 -> 0
B13: SG&A NC USD | E13: =[8]FYB26xFYMRF7!$D$15 -> 3800.2258 | H13: =[8]FYB26xFYMRF7!$G$15 -> 4339.9683 | J13: =E13-H13-I13 -> -539.74247
B14: Production | E14: =[8]FYB26xFYMRF7!$D$16 -> 133766.87 | H14: =[8]FYB26xFYMRF7!$G$16 -> 137770.92 | I14: =H14*($H$16/$E$16-1) -> -5772.4634 | J14: =E14-H14-I14 -> 1768.4223
B15: Production USD | E15: =[8]FYB26xFYMRF7!$D$17 -> 57260.893 | H15: =[8]FYB26xFYMRF7!$G$17 -> 56306.505 | J15: =E15-H15-I15 -> 954.38884
B16: Forex | E16: =[8]FYB26xFYMRF7!$B$23 -> 5.4 | H16: =[8]FYB26xFYMRF7!$B$24 -> 5.1737454
B17: Total Fixed Costs | E17: =SUM(E7:E15) -> 689471.18 | H17: =SUM(H7:H15) -> 752548.82 | I17: =SUM(I7:I15) -> -28787.082 | J17: =SUM(J7:J15) -> -34290.559
O62: =#REF! -> #REF!
O63: =

Sheet Forex
C2: FY
B3: ="EBITDA "&D15 -> EBITDA FY26'B | C3: =[1]DRE!$O$30/1000 -> 632.04404
B4: Forex | E4: Memória de calculo abaixo
B5: Price
B6: Volume
B7: Mix
B8: Fixed cost
B9: Input price
B10: Usage
B11: Others
B12: Stock variation
B13: ="EBITDA "&G15 -> EBITDA FY26'F7 | C13: =[2]DRE!$O$30/1000 -> 747.6924 | F13: =F48-F14 -> 0
C14: ='[3]Shipments & Prices'!$O$8*1000-C48 -> -0.38 | E14: =E48-'[3]Shipments & Prices'!$O$234 -> 0.1558374 | F14: ='[4]Shipments & Prices'!$O$20*1000 -> 7106558.5 | H14: ='[4]Shipments & Prices'!$O$234-H48 -> 0
D15: FY26'B | G15: FY26'F7
B16: Sales | C16: kt | D16: USD/t | E16: kUSD | F16: kt | G16: USD/t | H16: kUSD | I16: Sales Mix | J16: Mix Working | K16: Var Price USD | L16: Var Price BRL | M16: Price impact | O16: Var Price USD | P16: Price impact | Q16: Forex
B17: Slab Calvert | C17: ='[3]Shipments & Prices'!$O$23*1000 -> 961000 | D17: =IF(ISERROR((+E17/C17)*1000),0,(+E17/C17)*1000) -> 521.64672 | E17: ='[3]Shipments & Prices'!$O$237 -> 501302.5 | F17: ='[4]Shipments & Prices'!$O$23*1000 -> 966247.87 | G17: =IF(ISERROR((+H17/F17)*1000),0,(+H17/F17)*1000) -> 611.989 | H17: ='[4]Shipments & Prices'!$O$237 -> 591333.07 | I17: =(F17-J17)*D17/1000 -> 11455.529 | J17: =$F$48*C17/$C$48 -> 944287.55 | K17: =G17-D17 -> 90.342283 | M17: =K17*F17/1000 -> 87293.039 | O17: =G17-D17 -> 90.342283 | P17: =O17*F17/1000 -> 87293.039 | Q17: =P17-M17 -> 0
B18: Slabs Others Intragroup | C18: =[5]TUBARÃO_VEGA!$O$614*1000 -> 400000 | D18: =IF(ISERROR((+E18/C18)*1000),0,(+E18/C18)*1000) -> 444.574 | E18: =[5]TUBARÃO_VEGA!$O$626 -> 177829.6 | F18: ='[4]Shipments & Prices'!$O$614*1000 -> 997327.08 | G18: =IF(ISERROR((+H18/F18)*1000),0,(+H18/F18)*1000) -> 516.61738 | H18: ='[4]Shipments & Prices'!$O$626 -> 515236.51 | I18: =(F18-J18)*D18/1000 -> 268648.67 | J18: =$F$48*C18/$C$48 -> 393043.73 | K18: =G18-D18 -> 72.04338 | M18: =K18*F18/1000 -> 71850.814 | O18: =G18-D18 -> 72.04338 | P18: =O18*F18/1000 -> 71850.814 | Q18: =P18-M18 -> 0
B19: Slabs 3rd Party | C19: =[5]TUBARÃO_VEGA!$O$615*1000 -> 1423164.4 | D19: =IF(ISERROR((+E19/C19)*1000),0,(+E19/C19)*1000) -> 453.281 | E19: =[5]TUBARÃO_VEGA!$O$627 -> 645093.38 | F19: ='[4]Shipments & Prices'!$O$615*1000 -> 874385.04 | G19: =IF(ISERROR((+H19/F19)*1000),0,(+H19/F19)*1000) -> 520.32299 | H19: ='[4]Shipments & Prices'!$O$627 -> 454962.64 | I19: =(F19-J19)*D19/1000 -> -237532.63 | J19: =$F$48*C19/$C$48 -> 1398414.6 | K19: =G19-D19 -> 67.04199 | M19: =K19*F19/1000 -> 58620.514 | O19: =G19-D19 -> 67.04199 | P19: =O19*F19/1000 -> 58620.514 | Q19: =P19-M19 -> 0
B20: Slab DM | C20: ='[3]Shipments & Prices'!$O$25*1000 -> 31000 | D20: =IF(ISERROR((+E20/C20)*1000),0,(+E20/C20)*1000) -> 451.10154 | E20: ='[3]Shipments & Prices'!$O$239 -> 13984.148 | F20: ='[4]Shipments & Prices'!$O$25*1000 -> 32424.16 | G20: =IF(ISERROR((+H20/F20)*1000),0,(+H20/F20)*1000) -> 464.42371 | H20: ='[4]Shipments & Prices'!$O$239 -> 15058.549 | I20: =(F20-J20)*D20/1000 -> 885.6347 | J20: =$F$48*C20/$C$48 -> 30460.889 | L20: =(G20*$H$52)-(D20*$E$52) -> -31.991604 | M20: =L20*F20/1000/$E$52 -> -192.09276 | O20: =G20-D20 -> 13.32217 | P20: =O20*F20/1000 -> 431.96016 | Q20: =P20-M20 -> 624.05292
B21: Plates DM | C21: ='[3]Shipments & Prices'!$O$28*1000 -> 18000 | D21: =IF(ISERROR((+E21/C21)*1000),0,(+E21/C21)*1000) -> 685.40017 | E21: ='[3]Shipments & Prices'!$O$242 -> 12337.203 | F21: ='[4]Shipments & Prices'!$O$28*1000 -> 16529.16 | G21: =IF(ISERROR((+H21/F21)*1000),0,(+H21/F21)*1000) -> 700.72228 | H21: ='[4]Shipments & Prices'!$O$242 -> 11582.351 | I21: =(F21-J21)*D21/1000 -> -793.56156 | J21: =$F$48*C21/$C$48 -> 17686.968 | L21: =(G21*$H$52)-(D21*$E$52) -> -74.072135 | M21: =L21*F21/1000/$E$52 -> -226.73151 | O21: =G21-D21 -> 15.32211 | P21: =O21*F21/1000 -> 253.26161 | Q21: =P21-M21 -> 479.99312
B22: HRC Export | C22: ='[3]Shipments & Prices'!$O$30*1000 -> 433467 | D22: =IF(ISERROR((+E22/C22)*1000),0,(+E22/C22)*1000) -> 482.26451 | E22: ='[3]Shipments & Prices'!$O$244 -> 209045.75 | F22: ='[4]Shipments & Prices'!$O$30*1000 -> 197566.82 | G22: =IF(ISERROR((+H22/F22)*1000),0,(+H22/F22)*1000) -> 557.07307 | H22: ='[4]Shipments & Prices'!$O$244 -> 110059.16 | I22: =(F22-J22)*D22/1000 -> -110130.84 | J22: =$F$48*C22/$C$48 -> 425928.71 | K22: =G22-D22 -> 74.80856 | M22: =K22*F22/1000 -> 14779.689 | O22: =G22-D22 -> 74.80856 | P22: =O22*F22/1000 -> 14779.689 | Q22: =P22-M22 -> 0
B23: HRC DM Auto | C23: ='[3]Shipments & Prices'!$O$34*1000 -> 85817.96 | D23: =IF(ISERROR((+E23/C23)*1000),0,(+E23/C23)*1000) -> 681.44089 | E23: ='[3]Shipments & Prices'!$O$248 -> 58479.867 | F23: ='[4]Shipments & Prices'!$O$34*1000 -> 100236.84 | G23: =IF(ISERROR((+H23/F23)*1000),0,(+H23/F23)*1000) -> 725.82997 | H23: ='[4]Shipments & Prices'!$O$248 -> 72754.902 | I23: =(F23-J23)*D23/1000 -> 10842.62 | J23: =$F$48*C23/$C$48 -> 84325.527 | L23: =(G23*$H$52)-(D23*$E$52) -> 77.270714 | M23: =L23*F23/1000/$E$52 -> 1434.3282 | O23: =G23-D23 -> 44.38907 | P23: =O23*F23/1000 -> 4449.4202 | Q23: =P23-M23 -> 3015.092
B24: HRC DM Industry | C24: =('[3]Shipments & Prices'!$O$35)*1000 -> 1438681.3 | D24: =IF(ISERROR((+E24/C24)*1000),0,(+E24/C24)*1000) -> 658.77201 | E24: ='[3]Shipments & Prices'!$O$249 -> 947762.99 | F24: =('[4]Shipments & Prices'!$O$35)*1000 -> 1441770.7 | G24: =IF(ISERROR((+H24/F24)*1000),0,(+H24/F24)*1000) -> 693.84696 | H24: ='[4]Shipments & Prices'!$O$249 -> 1000368.2 | I24: =(F24-J24)*D24/1000 -> 18517.47 | J24: =$F$48*C24/$C$48 -> 1413661.7 | L24: =(G24*$H$52)-(D24*$E$52) -> 34.131787 | M24: =L24*F24/1000/$E$52 -> 9113.0022 | O24: =G24-D24 -> 35.074948 | P24: =O24*F24/1000 -> 50570.033 | Q24: =P24-M24 -> 41457.031
B25: HRC DM Downstream | C25: =+'[3]Shipments & Prices'!$O$36*1000 -> 427373.81 | D25: =IF(ISERROR((+E25/C25)*1000),0,(+E25/C25)*1000) -> 755.50415 | E25: =+'[3]Shipments & Prices'!$O$250 -> 322882.69 | F25: =+'[4]Shipments & Prices'!$O$36*1000 -> 446359.43 | G25: =IF(ISERROR((+H25/F25)*1000),0,(+H25/F25)*1000) -> 799.87146 | H25: ='[4]Shipments & Prices'!$O$250 -> 357030.17 | I25: =(F25-J25)*D25/1000 -> 19958.87 | J25: =$F$48*C25/$C$48 -> 419941.49 | L25: =(G25*$H$52)-(D25*$E$52) -> 60.583747 | M25: =L25*F25/1000/$E$52 -> 5007.8013 | O25: =G25-D25 -> 44.367302 | P25: =O25*F25/1000 -> 19803.764 | Q25: =P25-M25 -> 14795.962
B26: P&O DM Auto | C26: ='[3]Shipments & Prices'!$O$44*1000 -> 102999.19 | D26: =IF(ISERROR((+E26/C26)*1000),0,(+E26/C26)*1000) -> 859.20611 | E26: ='[3]Shipments & Prices'!$O$258 -> 88497.533 | F26: ='[4]Shipments & Prices'!$O$44*1000 -> 90523.858 | G26: =IF(ISERROR((+H26/F26)*1000),0,(+H26/F26)*1000) -> 914.47188 | H26: ='[4]Shipments & Prices'!$O$258 -> 82781.523 | I26: =(F26-J26)*D26/1000 -> -9179.8489 | J26: =$F$48*C26/$C$48 -> 101207.96 | L26: =(G26*$H$52)-(D26*$E$52) -> 93.789581 | M26: =L26*F26/1000/$E$52 -> 1572.2583 | O26: =G26-D26 -> 55.265775 | P26: =O26*F26/1000 -> 5002.8712 | Q26: =P26-M26 -> 3430.6129
B27: P&O DM Industry | C27: ='[3]Shipments & Prices'!$O$45*1000 -> 0 | D27: =G27 -> 723.2675 | E27: ='[3]Shipments & Prices'!$O$259 -> 0 | F27: ='[4]Shipments & Prices'!$O$45*1000 -> 45424.208 | G27: =IF(ISERROR((+H27/F27)*1000),0,(+H27/F27)*1000) -> 723.2675 | H27: ='[4]Shipments & Prices'!$O$259 -> 32853.853 | I27: =(F27-J27)*D27/1000 -> 32853.853 | J27: =$F$48*C27/$C$48 -> 0 | L27: =(G27*$H$52)-(D27*$E$52) -> -161.85682 | M27: =L27*F27/1000/$E$52 -> -1361.5219 | O27: =G27-D27 -> 0 | P27: =O27*F27/1000 -> 0 | Q27: =P27-M27 -> 1361.5219
B28: CRC EM Auto | C28: ='[3]Shipments & Prices'!$O$48*1000 -> 1220.3924 | D28: =IF(ISERROR((+E28/C28)*1000),0,(+E28/C28)*1000) -> 882.99234 | E28: ='[3]Shipments & Prices'!$O$262 -> 1077.5971 | F28: ='[4]Shipments & Prices'!$O$48*1000 -> 1887.8106 | G28: =IF(ISERROR((+H28/F28)*1000),0,(+H28/F28)*1000) -> 937.18709 | H28: ='[4]Shipments & Prices'!$O$262 -> 1769.2317 | I28: =(F28-J28)*D28/1000 -> 608.0653 | J28: =$F$48*C28/$C$48 -> 1199.1689 | L28: =(G28*$H$52)-(D28*$E$52) -> 82.922743 | M28: =L28*F28/1000/$E$52 -> 28.989339 | O28: =G28-D28 -> 54.194756 | P28: =O28*F28/1000 -> 102.30943 | Q28: =P28-M28 -> 73.320093
B29: CRC EM Industry | C29: ='[3]Shipments & Prices'!$O$49*1000 -> 492.26 | D29: =IF(ISERROR((+E29/C29)*1000),0,(+E29/C29)*1000) -> 323.31493 | E29: ='[3]Shipments & Prices'!$O$263 -> 159.15501 | F29: ='[4]Shipments & Prices'!$O$49*1000 -> 4847.375 | G29: =IF(ISERROR((+H29/F29)*1000),0,(+H29/F29)*1000) -> 603.52341 | H29: ='[4]Shipments & Prices'!$O$263 -> 2925.5043 | I29: =(F29-J29)*D29/1000 -> 1410.8415 | J29: =$F$48*C29/$C$48 -> 483.69926 | K29: =G29-D29 -> 280.20848 | M29: =K29*F29/1000 -> 1358.2756 | O29: =G29-D29 -> 280.20848 | P29: =O29*F29/1000 -> 1358.2756 | Q29: =P29-M29 -> 0
B30: CRC DM Auto | C30: ='[3]Shipments & Prices'!$O$51*1000 -> 90127.47 | D30: =IF(ISERROR((+E30/C30)*1000),0,(+E30/C30)*1000) -> 922.02223 | E30: ='[3]Shipments & Prices'!$O$265 -> 83099.531 | F30: ='[4]Shipments & Prices'!$O$51*1000 -> 95622.293 | G30: =IF(ISERROR((+H30/F30)*1000),0,(+H30/F30)*1000) -> 982.99579 | H30: ='[4]Shipments & Prices'!$O$265 -> 93996.312 | I30: =(F30-J30)*D30/1000 -> 6511.5067 | J30: =$F$48*C30/$C$48 -> 88560.092 | L30: =(G30*$H$52)-(D30*$E$52) -> 109.27698 | M30: =L30*F30/1000/$E$52 -> 1935.0584 | O30: =G30-D30 -> 60.973563 | P30: =O30*F30/1000 -> 5830.4319 | Q30: =P30-M30 -> 3895.3736
B31: CRC DM Industry | C31: =('[3]Shipments & Prices'!$O$52)*1000 -> 265325.54 | D31: =IF(ISERROR((+E31/C31)*1000),0,(+E31/C31)*1000) -> 788.21579 | E31: ='[3]Shipments & Prices'!$O$266 -> 209133.78 | F31: =('[4]Shipments & Prices'!$O$52)*1000 -> 286122.32 | G31: =IF(ISERROR((+H31/F31)*1000),0,(+H31/F31)*1000) -> 844.90554 | H31: ='[4]Shipments & Prices'!$O$266 -> 241746.33 | I31: =(F31-J31)*D31/1000 -> 20029.329 | J31: =$F$48*C31/$C$48 -> 260711.35 | L31: =(G31*$H$52)-(D31*$E$52) -> 117.04702 | M31: =L31*F31/1000/$E$52 -> 6201.8085 | O31: =G31-D31 -> 56.689756 | P31: =O31*F31/1000 -> 16220.205 | Q31: =P31-M31 -> 10018.396
B32: CRC DM Downstream | C32: =+'[3]Shipments & Prices'!$O$53*1000 -> 110301.97 | D32: =IF(ISERROR((+E32/C32)*1000),0,(+E32/C32)*1000) -> 833.50042 | E32: =+'[3]Shipments & Prices'!$O$267 -> 91936.738 | F32: =+'[4]Shipments & Prices'!$O$53*1000 -> 117390.91 | G32: =IF(ISERROR((+H32/F32)*1000),0,(+H32/F32)*1000) -> 892.1814 | H32: =+'[4]Shipments & Prices'!$O$267 -> 104733.99 | I32: =(F32-J32)*D32/1000 -> 7507.4783 | J32: =$F$48*C32/$C$48 -> 108383.74 | L32: =(G32*$H$52)-(D32*$E$52) -> 117.21996 | M32: =L32*F32/1000/$E$52 -> 2548.2515 | O32: =G32-D32 -> 58.680977 | P32: =O32*F32/1000 -> 6888.6133 | Q32: =P32-M32 -> 4340.3619
B33: HDG EM Auto | C33: ='[3]Shipments & Prices'!$O$61*1000 -> 49551.853 | D33: =IF(ISERROR((+E33/C33)*1000),0,(+E33/C33)*1000) -> 1018.0181 | E33: ='[3]Shipments & Prices'!$O$275 -> 50444.681 | F33: ='[4]Shipments & Prices'!$O$61*1000 -> 41148.524 | G33: =IF(ISERROR((+H33/F33)*1000),0,(+H33/F33)*1000) -> 1058.4157 | H33: ='[4]Shipments & Prices'!$O$275 -> 43552.244 | I33: =(F33-J33)*D33/1000 -> -7677.4736 | J33: =$F$48*C33/$C$48 -> 48690.112 | L33: =(G33*$H$52)-(D33*$E$52) -> -18.710747 | M33: =L33*F33/1000/$E$52 -> -142.57771 | O33: =G33-D33 -> 40.397668 | P33: =O33*F33/1000 -> 1662.3044 | Q33: =P33-M33 -> 1804.8821
B34: HDG EM Industry | C34: ='[3]Shipments & Prices'!$O$62*1000 -> 1014.12 | D34: =IF(ISERROR((+E34/C34)*1000),0,(+E34/C34)*1000) -> 323.31493 | E34: ='[3]Shipments & Prices'!$O$276 -> 327.88014 | F34: ='[4]Shipments & Prices'!$O$62*1000 -> 2599.121 | G34: =IF(ISERROR((+H34/F34)*1000),0,(+H34/F34)*1000) -> 562.09665 | H34: ='[4]Shipments & Prices'!$O$276 -> 1460.9572 | I34: =(F34-J34)*D34/1000 -> 518.15655 | J34: =$F$48*C34/$C$48 -> 996.48376 | K34: =G34-D34 -> 238.78171 | M34: =K34*F34/1000 -> 620.62257 | O34: =G34-D34 -> 238.78171 | P34: =O34*F34/1000 -> 620.62257 | Q34: =P34-M34 -> 0
B35: HDG DM Auto | C35: ='[3]Shipments & Prices'!$O$64*1000 -> 463694.03 | D35: =IF(ISERROR((+E35/C35)*1000),0,(+E35/C35)*1000) -> 1045.0986 | E35: ='[3]Shipments & Prices'!$O$278 -> 484605.99 | F35: ='[4]Shipments & Prices'!$O$64*1000 -> 463787.29 | G35: =IF(ISERROR((+H35/F35)*1000),0,(+H35/F35)*1000) -> 1098.849 | H35: ='[4]Shipments & Prices'!$O$278 -> 509632.21 | I35: =(F35-J35)*D35/1000 -> 8525.0978 | J35: =$F$48*C35/$C$48 -> 455630.07 | L35: =(G35*$H$52)-(D35*$E$52) -> 44.345684 | M35: =L35*F35/1000/$E$52 -> 3808.6971 | O35: =G35-D35 -> 53.750413 | P35: =O35*F35/1000 -> 24928.758 | Q35: =P35-M35 -> 21120.061
B36: HDG DM Industry | C36: =('[3]Shipments & Prices'!$O$65)*1000 -> 416584.71 | D36: =IF(ISERROR((+E36/C36)*1000),0,(+E36/C36)*1000) -> 848.78295 | E36: ='[3]Shipments & Prices'!$O$279 -> 353590 | F36: =('[4]Shipments & Prices'!$O$65)*1000 -> 438619.17 | G36: =IF(ISERROR((+H36/F36)*1000),0,(+H36/F36)*1000) -> 912.55186 | H36: ='[4]Shipments & Prices'!$O$279 -> 400262.74 | I36: =(F36-J36)*D36/1000 -> 24851.647 | J36: =$F$48*C36/$C$48 -> 409340.02 | L36: =(G36*$H$52)-(D36*$E$52) -> 140.13614 | M36: =L36*F36/1000/$E$52 -> 11382.666 | O36: =G36-D36 -> 63.768902 | P36: =O36*F36/1000 -> 27970.263 | Q36: =P36-M36 -> 16587.597
B37: HDG DM Downstream | C37: =+'[3]Shipments & Prices'!$O$66*1000 -> 83539.33 | D37: =IF(ISERROR((+E37/C37)*1000),0,(+E37/C37)*1000) -> 880.30207 | E37: =+'[3]Shipments & Prices'!$O$280 -> 73539.846 | F37: =+'[4]Shipments & Prices'!$O$66*1000 -> 76159.621 | G37: =IF(ISERROR((+H37/F37)*1000),0,(+H37/F37)*1000) -> 950.63961 | H37: =+'[4]Shipments & Prices'!$O$280 -> 72400.352 | I37: =(F37-J37)*D37/1000 -> -5217.4647 | J37: =$F$48*C37/$C$48 -> 82086.524 | L37: =(G37*$H$52)-(D37*$E$52) -> 167.08325 | M37: =L37*F37/1000/$E$52 -> 2356.481 | O37: =G37-D37 -> 70.337531 | P37: =O37*F37/1000 -> 5356.8797 | Q37: =P37-M37 -> 3000.3988
B38: AlZn Export | C38: ='[3]Shipments & Prices'!$O$74*1000 -> 0 | D38: =IF(ISERROR((+E38/C38)*1000),0,(+E38/C38)*1000) -> 0 | E38: ='[3]Shipments & Prices'!$O$288 -> 0 | F38: ='[4]Shipments & Prices'!$O$74*1000 -> 0 | G38: =IF(ISERROR((+H38/F38)*1000),0,(+H38/F38)*1000) -> 0 | H38: ='[4]Shipments & Prices'!$O$288 -> 0 | I38: =(F38-J38)*D38/1000 -> 0 | J38: =$F$48*C38/$C$48 -> 0 | K38: =G38-D38 -> 0 | M38: =K38*F38/1000 -> 0 | O38: =G38-D38 -> 0 | P38: =O38*F38/1000 -> 0 | Q38: =P38-M38 -> 0
B39: AlZn DM Industry | C39: =('[3]Shipments & Prices'!$O$79)*1000 -> 181457.09 | D39: =IF(ISERROR((+E39/C39)*1000),0,(+E39/C39)*1000) -> 973.02161 | E39: ='[3]Shipments & Prices'!$O$293 -> 176561.67 | F39: =('[4]Shipments & Prices'!$O$79)*1000 -> 136271.79 | G39: =IF(ISERROR((+H39/F39)*1000),0,(+H39/F39)*1000) -> 1027.641 | H39: ='[4]Shipments & Prices'!$O$293 -> 140038.48 | I39: =(F39-J39)*D39/1000 -> -40895.746 | J39: =$F$48*C39/$C$48 -> 178301.43 | L39: =(G39*$H$52)-(D39*$E$52) -> 64.973401 | M39: =L39*F39/1000/$E$52 -> 1639.6373 | O39: =G39-D39 -> 54.619373 | P39: =O39*F39/1000 -> 7443.0797 | Q39: =P39-M39 -> 5803.4424
B40: ALZn DM Downstream | C40: =+'[3]Shipments & Prices'!$O$80*1000 -> 106335.88 | D40: =IF(ISERROR((+E40/C40)*1000),0,(+E40/C40)*1000) -> 1088.1106 | E40: =+'[3]Shipments & Prices'!$O$294 -> 115705.2 | F40: =+'[4]Shipments & Prices'!$O$80*1000 -> 88523.367 | G40: =IF(ISERROR((+H40/F40)*1000),0,(+H40/F40)*1000) -> 1184.3833 | H40: =+'[4]Shipments & Prices'!$O$294 -> 104845.6 | I40: =(F40-J40)*D40/1000 -> -17369.792 | J40: =$F$48*C40/$C$48 -> 104486.63 | L40: =(G40*$H$52)-(D40*$E$52) -> 254.82436 | M40: =L40*F40/1000/$E$52 -> 4177.3908 | O40: =G40-D40 -> 96.272637 | P40: =O40*F40/1000 -> 8522.378 | Q40: =P40-M40 -> 4344.9871
B41: Usibor DM Auto | C41: ='[3]Shipments & Prices'!$O$90*1000 -> 94231.595 | D41: =IF(ISERROR((+E41/C41)*1000),0,(+E41/C41)*1000) -> 1291.3711 | E41: ='[3]Shipments & Prices'!$O$304 -> 121687.96 | F41: ='[4]Shipments & Prices'!$O$90*1000 -> 99323.021 | G41: =IF(ISERROR((+H41/F41)*1000),0,(+H41/F41)*1000) -> 1381.2513 | H41: ='[4]Shipments & Prices'!$O$304 -> 137190.05 | I41: =(F41-J41)*D41/1000 -> 8691.1575 | J41: =$F$48*C41/$C$48 -> 92592.843 | L41: =(G41*$H$52)-(D41*$E$52) -> 176.24927 | M41: =L41*F41/1000/$E$52 -> 3241.7797 | O41: =G41-D41 -> 89.880255 | P41: =O41*F41/1000 -> 8927.1784 | Q41: =P41-M41 -> 5685.3988
...

Sheet SV-Others
B2: O restante não explicado.
B3: No segundo momento, criar os modelos matemáticos automaticos para pegar o cálculo do forex from inventories, stock variation, legal contingency, invest-ES, etc

Sheet EBITDA
B2: Inicialmente pegar os valores do EBITDA do FCF

Sheet Bridge
